Workbook
Name CS: CS!$A$2:$K$38
Name CS_test: #REF!
Name Impact: 'S00 Impact'!$A$1:$H$40
Name ImpactAir: #REF!

Sheet Rail
A1: All prices are i 2025 price level year | C1: AP train persons | D1: AP train freight | E1: GW train person | F1: GW train freight | G1: Accidents - train passengers | H1: Noise - train passengers | I1: Accidents - train freight | J1: Noise - train freight
B2: Country | C2: € cent/pkm | D2: € cent/tkm | E2: € cent/pkm | F2: € cent/tkm | G2: €ct/pkm | H2: €ct/pkm | I2: €ct/tkm | J2: €ct/tkm
A3: AL | B3: Albania | C3: 0.021 | D3: 0.019 | E3: 0.152 | F3: 0.087 | G3: 0.052 | H3: 0.145 | I3: 0.027 | J3: 0.039
A4: AT | B4: Austria | C4: 0.032 | D4: 0.011 | E4: 0.152 | F4: 0.087 | G4: 0.112 | H4: 0.114 | I4: 0.031 | J4: 0.141
A5: BA | B5: Belarus | C5: 0.078 | D5: 0.045 | E5: 0.152 | F5: 0.087 | G5: 0.074 | H5: 0.134 | I5: 0.027 | J5: 0.038
A6: BE | B6: Belgium | C6: 0.366 | D6: 0.211 | E6: 0.152 | F6: 0.087 | G6: 0.071 | H6: 0.04 | I6: 0.025 | J6: 0.066
A7: BG | B7: Bulgaria | C7: 0.047 | D7: 0.027 | E7: 0.152 | F7: 0.087 | G7: 0.085 | H7: 0.215 | I7: 0.027 | J7: 0.03
A8: BY | B8: Bonsnia & Herzegovina | C8: 0.074 | D8: 0.044 | E8: 0.152 | F8: 0.087 | G8: 0.071 | H8: 0.031 | I8: 0.027 | J8: 0.034
A9: CH | B9: Switzerland | C9: 0.04 | D9: 0.023 | E9: 0.152 | F9: 0.087 | G9: 0.138 | H9: 0.22 | I9: 0.014 | J9: 0.059
A10: CZ | B10: Czech Republic | C10: 0.081 | D10: 0.043 | E10: 0.152 | F10: 0.087 | G10: 0.055 | H10: 0.1 | I10: 0.028 | J10: 0.128
A11: DE | B11: Germany | C11: 0.035 | D11: 0.02 | E11: 0.152 | F11: 0.087 | G11: 0.085 | H11: 0.143 | I11: 0.027 | J11: 0.038
A12: DK | B12: Denmark | C12: 0.046 | D12: 0.031 | E12: 0.152 | F12: 0.087 | G12: 0.057 | H12: 0.053 | I12: 0.031 | J12: 0.128
A13: EE | B13: Estonia | C13: 0.318 | D13: 0.183 | E13: 0.152 | F13: 0.087 | G13: 0.071 | H13: 0.038 | I13: 0.034 | J13: 0.198
A14: ES | B14: Spain | C14: 0.033 | D14: 0.019 | E14: 0.152 | F14: 0.087 | G14: 0.064 | H14: 0.163 | I14: 0.027 | J14: 0.029
... A41: YU | B41: Yugoslavia | C41: 0.042 | D41: 0.024 | E41: 0.152 | F41: 0.087 | G41: 0.071 | H41: 0.038 | I41: 0.027 | J41: 0.049

Sheet Full overview
A1: Scenario | C1: Type | D1: Investment costs (M€) | E1: Change in maintenance costs (M€/year) | G1: Opening year | H1: Construction period (year)
A2: 1 | B2: Munich - Verona | C2: Railway | D2: 14000 | E2: 7.4 | G2: 2030 | H2: 10
A3: 2 | B3: Naples - Messina | C3: Railway | D3: 6770 | E3: 4.7 | F3: * | G3: 2026 | H3: 7
A4: 3 | B4: Coimbra - Madrid (incl. upgrades) | C4: Railway + road | D4: 3870 | E4: 9.9 | G4: 2028 | H4: 7
A5: 4 | B5: North-west Spain | C5: Railway passenger | D5: 870 | E5: 9.1 | G5: 2026 | H5: 6
A6: 5 | B6: Bordeaux - San Sebastian (incl. upgrades) | C6: Railway + road | D6: 5570 | E6: 14.2 | G6: 2027 | H6: 7
A7: 6 | B7: Montpellier - Perpignan (incl. upgrades) | C7: Railway + road | D7: 7670 | E7: 8.2 | G7: 2029 | H7: 7
A8: 7 | B8: Saarbrucken - Morhange (incl. upgrades) | C8: Railway | D8: 930 | E8: 2.8 | G8: 2026 | H8: 6
A9: 8 | B9: Chambery - Torino | C9: Railway | D9: 6020 | E9: 1.7 | G9: 2027 | H9: 7
A10: 9 | B10: Milan - Hungary-Ukrane + Nove Zamky - Budapest | C10: Railway | D10: 23380 | E10: 7.6 | G10: 2030 | H10: 10
A11: 10 | B11: Hungary - Romania + Bulgary - Greece | C11: Railway + road | D11: 9870 | E11: 2.4 | G11: 2028 | H11: 8
A12: 11 | B12: Sibiu - Pitesti + Deva - Brasov | C12: Railway + road | D12: 4740 | E12: 1.8 | G12: 2028 | H12: 7
A13: 12 | B13: South of Finland | C13: Railway + road | D13: 2740 | E13: 1.7 | G13: 2027 | H13: 6
A14: 13 | B14: Nyköping - Södertälje | C14: Railway | D14: 2300 | E14: 0 | G14: 2026 | H14: 6
A15: 14 | B15: Stuttgart - Linz - Prague | C15: Railway + road | D15: 6240 | E15: 0.2 | G15: 2027 | H15: 7
... A37: 36 | B37: Belgian-French border - Compiegne | C37: Waterway | D37: 1250 | E37: 2.5 | G37: 2028 | H37: 6
A40: * | D40: Includes the bridge over the strait of Messina (4685 M€)

Sheet CS
A1: Consumers surplus for year | E1: 2035
A2: scenario | B2: Opening year | C2: CS_passenger | D2: CS_CarD | E2: CS_CarP | F2: CS_Air | G2: CS_Rail | H2: CS_freight | I2: CS_freight_Truck | J2: CS_freight_Rail | K2: CS_freight_IWW | M2: CS is calculated for 2035 and measured in 2025 prices
A3: 01 | B3: 2030 | C3: =SUM(D3:G3) -> 25814639 | D3: 3292020.1 | E3: 779110.84 | F3: 523558.63 | G3: 21219949 | H3: =SUM(I3:K3) -> 43975545 | I3: 41181339 | J3: 2794206.5 | K3: 0
A4: 02 | B4: 2026 | C4: =SUM(D4:G4) -> 35989224 | D4: 874796.51 | E4: 9256946.2 | F4: 474148.16 | G4: 25383333 | H4: =SUM(I4:K4) -> 346361.51 | I4: 0 | J4: 346361.51 | K4: 0 | M4: Conforms to the rule-of-a-half approximation
A5: 03 | B5: 2028 | C5: =SUM(D5:G5) -> 28491754 | D5: 25427347 | E5: -4651241.1 | F5: 1534941.8 | G5: 6180706.3 | H5: =SUM(I5:K5) -> 64500020 | I5: 64507209 | J5: -7189.5787 | K5: 0
A6: 04 | B6: 2026 | C6: =SUM(D6:G6) -> 12321237 | D6: 18800697 | E6: -10653150 | F6: 830984.59 | G6: 3342704.3 | H6: 12232479 | I6: 12201238 | J6: 31240.881 | K6: 0
A7: 05 | B7: 2027 | C7: =SUM(D7:G7) -> 92462354 | D7: 41582639 | E7: 9523842.4 | F7: 2780312.6 | G7: 38575561 | H7: =SUM(I7:K7) -> 12146614 | I7: 11835689 | J7: 310925.05 | K7: 0
A8: 06 | B8: 2029 | C8: =SUM(D8:G8) -> 3.8088879e+08 | D8: 2.5156145e+08 | E8: 1.0212076e+08 | F8: 1673009.3 | G8: 25533575 | H8: =SUM(I8:K8) -> 16361880 | I8: 13158877 | J8: 3203002.7 | K8: 0
A9: 07 | B9: 2026 | C9: =SUM(D9:G9) -> 16376222 | D9: -8352863.8 | E9: 8436954 | F9: 2642290.2 | G9: 13649841 | H9: =SUM(I9:K9) -> 2041799 | I9: 0 | J9: 2041799 | K9: 0
A10: 08 | B10: 2027 | C10: =SUM(D10:G10) -> 32671112 | D10: 11078106 | E10: 5293693.5 | F10: 1487546 | G10: 14811766 | H10: =SUM(I10:K10) -> 342465.87 | I10: 0 | J10: 342465.87 | K10: 0
A11: 09 | B11: 2030 | C11: =SUM(D11:G11) -> 8.067075e+08 | D11: 2.2953128e+08 | E11: 1.0780196e+08 | F11: 9569090 | G11: 4.5980517e+08 | H11: =SUM(I11:K11) -> 1.6244622e+08 | I11: 0 | J11: 1.6244622e+08 | K11: 0
A12: 10 | B12: 2028 | C12: =SUM(D12:G12) -> 2.8634481e+08 | D12: 1.3885025e+08 | E12: 48792286 | F12: 3049162.9 | G12: 95653114 | H12: 1.8307176e+08 | I12: 65226931 | J12: 1.1784482e+08 | K12: 0
A13: 11 | B13: 2028 | C13: =SUM(D13:G13) -> 1.4024007e+08 | D13: 98022962 | E13: 22920118 | F13: -376642.74 | G13: 19673628 | H13: =SUM(I13:K13) -> 1.4563944e+08 | I13: 91542939 | J13: 54096505 | K13: 0
A14: 12 | B14: 2027 | C14: =SUM(D14:G14) -> 36250561 | D14: 5327724.8 | E14: 10082210 | F14: 361984.49 | G14: 20478641 | H14: =SUM(I14:K14) -> 62457048 | I14: 35941454 | J14: 26515595 | K14: 0
A15: 13 | B15: 2026 | C15: =SUM(D15:G15) -> 27000735 | D15: 14593105 | E15: -1147100.2 | F15: 1137161.2 | G15: 12417569 | H15: =SUM(I15:K15) -> 2794206.5 | I15: 0 | J15: 2794206.5 | K15: 0
A16: 14 | B16: 2027 | C16: =SUM(D16:G16) -> 57227570 | D16: -2400919.9 | E16: -11566817 | F16: 7157099.4 | G16: 64038207 | H16: =SUM(I16:K16) -> 36832502 | I16: -5395036.1 | J16: 42227539 | K16: 0
A17: 15 | B17: 2027 | C17: =SUM(D17:G17) -> 1.1125133e+08 | D17: 36128921 | E17: 3885548.2 | F17: 10084067 | G17: 61152797 | H17: =SUM(I17:K17) -> 2.608117e+08 | I17: 99676380 | J17: 1.6113532e+08 | K17: 0
A18: 16 | B18: 2028 | C18: =SUM(D18:G18) -> 31295837 | D18: 17677533 | E18: 7315689.3 | F18: 1086287.5 | G18: 5216327.6 | H18: =SUM(I18:K18) -> 416020.15 | I18: 0 | J18: 416020.15 | K18: 0
A19: 17 | B19: 2027 | C19: =SUM(D19:G19) -> 18260970 | D19: 11938868 | E19: 3977513.7 | F19: 1545219.7 | G19: 799369.18 | H19: =SUM(I19:K19) -> 1387938.4 | I19: 0 | J19: 1387938.4 | K19: 0
A20: 18 | B20: 2029 | C20: =SUM(D20:G20) -> 1.0090258e+08 | D20: -2604051.6 | E20: 332222.07 | F20: 1076177.2 | G20: 1.0209824e+08 | H20: =SUM(I20:K20) -> 49153274 | I20: 41883980 | J20: 7269294.2 | K20: 0
A21: 19 | B21: 2026 | C21: =SUM(D21:G21) -> 38326682 | D21: 15194980 | E21: -9255131.2 | F21: 860433.36 | G21: 31526399 | H21: =SUM(I21:K21) -> 15557414 | I21: 3618021.3 | J21: 11939393 | K21: 0
A22: 20 | B22: 2027 | C22: =SUM(D22:G22) -> 67568116 | D22: 38349040 | E22: 3310327.9 | F22: 1475435.1 | G22: 24433313 | H22: =SUM(I22:K22) -> 26603746 | I22: 22160113 | J22: 4443632.7 | K22: 0
A23: 21 | B23: 2027 | C23: =SUM(D23:G23) -> 1.5641985e+08 | D23: 55571260 | E23: 29590106 | F23: 1230879.8 | G23: 70027607 | H23: =SUM(I23:K23) -> 3.4320803e+08 | I23: 2.1804485e+08 | J23: 1.2516318e+08 | K23: 0
A24: 22 | B24: 2028 | C24: =SUM(D24:G24) -> 36230828 | D24: 22710529 | E24: 6437491.7 | F24: 1656655.4 | G24: 5426152.3 | H24: =SUM(I24:K24) -> -26444396 | I24: -26525365 | J24: 80968.644 | K24: 0
... A38: 36 | B38: 2028 | C38: =SUM(D38:G38) -> 13987888 | D38: 1804712.7 | E38: 9426554.1 | F38: 1749114.6 | G38: 1007506.2 | H38: =SUM(I38:K38) -> 18428154 | I38: 0 | J38: 0 | K38: 18428154

Sheet Road
A1: All prices are i 2025 price level year | D1: Ap_car_petrol | E1: Ap_car_diesel | F1: Gw_car_petrol | G1: GW car diesel | H1: AP hgv diesel | I1: GW hgv diesel | J1: Accidents car | K1: Noise car | L1: Accidents - HGV | M1: Noise - HGV
B2: Country | D2: €ct/vkm | E2: €ct/vkm | F2: €ct/vkm | G2: €ct/vkm | H2: €ct/vkm | I2: €ct/vkm | J2: €ct/vkm | K2: €ct/vkm | L2: €ct/vkm | M2: €ct/vkm
A3: AL | B3: Albania | D3: 0.105 | E3: 0.297 | F3: 0.959 | G3: 0.956 | H3: 2.269 | I3: 4.453 | J3: 0.413 | K3: 0.34 | L3: 1.313 | M3: 2.949
A4: AT | B4: Austria | D4: 0.165 | E4: 0.649 | F4: 0.96 | G4: 0.955 | H4: 5.185 | I4: 4.453 | J4: 0.5 | K4: 0.713 | L4: 5.024 | M4: 4.707
A5: BA | B5: Belarus | D5: 0.09 | E5: 0.256 | F5: 0.959 | G5: 0.956 | H5: 1.95 | I5: 4.453 | J5: 0.355 | K5: 0.293 | L5: 1.128 | M5: 2.534
A6: BE | B6: Belgium | D6: 0.161 | E6: 0.462 | F6: 0.96 | G6: 0.955 | H6: 3.467 | I6: 4.453 | J6: 0.573 | K6: 0.658 | L6: 9.729 | M6: 4.345
A7: BG | B7: Bulgaria | D7: 0.08 | E7: 0.227 | F7: 0.959 | G7: 0.956 | H7: 1.735 | I7: 4.453 | J7: 0.315 | K7: 0.26 | L7: 1.004 | M7: 2.255
A8: BY | B8: Bonsnia & Herzegovina | D8: 0.101 | E8: 0.285 | F8: 0.959 | G8: 0.956 | H8: 2.177 | I8: 4.453 | J8: 0.396 | K8: 0.327 | L8: 1.259 | M8: 2.829
A9: CH | B9: Switzerland | D9: 0.309 | E9: 0.873 | F9: 0.959 | G9: 0.956 | H9: 6.662 | I9: 4.453 | J9: 1.211 | K9: 1 | L9: 3.855 | M9: 8.658
A10: CZ | B10: Czech Republic | D10: 0.145 | E10: 0.414 | F10: 0.96 | G10: 0.955 | H10: 3.162 | I10: 4.453 | J10: 0.222 | K10: 0.494 | L10: 1.947 | M10: 4.841
A11: DE | B11: Germany | D11: 0.148 | E11: 0.612 | F11: 0.96 | G11: 0.955 | H11: 4.924 | I11: 4.453 | J11: 0.38 | K11: 0.584 | L11: 3.853 | M11: 3.856
A12: DK | B12: Denmark | D12: 0.138 | E12: 0.365 | F12: 0.96 | G12: 0.955 | H12: 2.762 | I12: 4.453 | J12: 0.39 | K12: 0.858 | L12: 3.583 | M12: 5.663
A13: EE | B13: Estonia | D13: 0.207 | E13: 0.589 | F13: 0.96 | G13: 0.955 | H13: 4.5 | I13: 4.453 | J13: 0.225 | K13: 0.703 | L13: 2.771 | M13: 6.888
A14: ES | B14: Spain | D14: 0.17 | E14: 0.341 | F14: 0.96 | G14: 0.955 | H14: 2.433 | I14: 4.453 | J14: 0.451 | K14: 0.574 | L14: 0.496 | M14: 3.789
... A41: YU | B41: Yugoslavia | D41: 0.09 | E41: 0.256 | F41: 0.959 | G41: 0.956 | H41: 1.95 | I41: 4.453 | J41: 0.355 | K41: 0.293 | L41: 1.128 | M41: 2.534

Sheet Air
A1: All prices are i 2025 price level year | C1: Air pollution - air | D1: Global warming - air
B2: Country | C2: €ct/pkm | D2: €ct/pkm
B3: All countries | C3: 0.688 | D3: 0.499

Sheet IWW
A1: All prices are i 2025 price level year | C1: Air pollution - IWW | D1: Global warming IWW
B2: Country | C2: €ct/tkm | D2: €ct/tkm
A3: AL | B3: Albania | C3: 1.876 | D3: 0.272
A4: AT | B4: Austria | C4: 2.521 | D4: 0.272
A5: BA | B5: Belarus | C5: 1.876 | D5: 0.272
A6: BE | B6: Belgium | C6: 2.236 | D6: 0.272
A7: BG | B7: Bulgaria | C7: 0.47 | D7: 0.272
A8: BY | B8: Bonsnia & Herzegovina | C8: 1.876 | D8: 0.272
A9: CH | B9: Switzerland | C9: 1.876 | D9: 0.272
A10: CZ | B10: Czech Republic | C10: 1.876 | D10: 0.272
A11: DE | B11: Germany | C11: 2.429 | D11: 0.272
A12: DK | B12: Denmark | C12: 2.684 | D12: 0.272
A13: EE | B13: Estonia | C13: 1.876 | D13: 0.272
A14: ES | B14: Spain | C14: 1.876 | D14: 0.272
... A41: YU | B41: Yugoslavia | C41: 1.272 | D41: 0.272

Sheet S00 Impact
A1: Scenario | B1: CountryCode | C1: vkm_petrol_Carpassenger | D1: vkm_diesel_Carpassenger | E1: vkm_hgv_Freight | F1: Total_IWW_TonKM | G1: PersonKM_RailPassenger | H1: TonKM_RailFreight | J1: _TYPE_ | K1: _FREQ_ | L1: personkm_Air
A2: 0 | B2: AL | C2: 2.1980666e+09 | D2: 5.4375694e+08 | E2: 7.772212e+08 | G2: 1.2697104e+08 | H2: 5.9557851e+08 | J2: 0 | K2: 3153 | L2: 8.392938e+11
A3: 0 | B3: AT | C3: 4.3085971e+10 | D3: 2.7049782e+10 | E3: 6.8853187e+09 | F3: 7.1064248e+09 | G3: 1.5860344e+10 | H3: 2.4759775e+10
A4: 0 | B4: BA | C4: 5.0277972e+09 | D4: 1.2335822e+09 | E4: 8.434936e+08 | F4: 7.3871775e+08 | G4: 5.9999837e+08 | H4: 1.2084542e+09
A5: 0 | B5: BE | C5: 4.2897807e+10 | D5: 3.255379e+10 | E5: 8.4078117e+09 | F5: 9.5886557e+09 | G5: 1.4152909e+10 | H5: 9.8150371e+09
A6: 0 | B6: BG | C6: 2.7971419e+10 | D6: 6.8351173e+09 | E6: 3.8406982e+09 | F6: 2.1006345e+09 | G6: 1.700996e+10 | H6: 2.3009823e+10
A7: 0 | B7: BY | C7: 1.9233009e+10 | D7: 4.6363897e+09 | E7: 1.043522e+10 | G7: 7.7116123e+09 | H7: 2.6951466e+10
A8: 0 | B8: CH | C8: 3.9946537e+10 | D8: 5.7129371e+09 | E8: 3.6435066e+09 | F8: 38941402 | G8: 1.1678971e+10 | H8: 1.1557304e+10
A9: 0 | B9: CZ | C9: 3.1730503e+10 | D9: 6.8905019e+09 | E9: 8.547688e+09 | F9: 45302166 | G9: 9.3607733e+09 | H9: 3.5367292e+10
A10: 0 | B10: DE | C10: 3.8000961e+11 | D10: 8.867191e+10 | E10: 4.652768e+10 | F10: 7.5684748e+10 | G10: 1.1489967e+11 | H10: 1.1011037e+11
A11: 0 | B11: DK | C11: 3.7244767e+10 | D11: 3.8658467e+09 | E11: 7.2427306e+09 | G11: 6.3847484e+09 | H11: 3.3950105e+09
A12: 0 | B12: EE | C12: 3.3566489e+09 | D12: 6.0964292e+08 | E12: 1.8199685e+09 | G12: 2.9024163e+08 | H12: 3.0995576e+10
A13: 0 | B13: ES | C13: 1.7610576e+11 | D13: 9.4465086e+10 | E13: 4.8189133e+10 | G13: 2.9510205e+10 | H13: 2.4316358e+10
A14: 0 | B14: FI | C14: 2.9660486e+10 | D14: 4.3296043e+09 | E14: 5.6539688e+09 | G14: 7.6550922e+09 | H14: 2.2105141e+10
A15: 0 | B15: FR | C15: 2.4535292e+11 | D15: 1.677295e+11 | E15: 4.404751e+10 | F15: 1.2023247e+10 | G15: 9.5137533e+10 | H15: 5.5777392e+10
A16: 0 | B16: GR | C16: 2.7384386e+10 | D16: 6.7792426e+09 | E16: 6.2845605e+09 | G16: 2.9315963e+09 | H16: 1.4283851e+09
A17: 0 | B17: HR | C17: 2.2445419e+10 | D17: 5.5769196e+09 | E17: 2.6703844e+09 | F17: 3.1189513e+08 | G17: 9.1561312e+09 | H17: 7.5068775e+09
A18: 0 | B18: HU | C18: 2.9563781e+10 | D18: 6.0743789e+09 | E18: 5.3968855e+09 | F18: 1.1182449e+10 | G18: 1.5426045e+10 | H18: 2.3852046e+10
A19: 0 | B19: IE | C19: 2.7587363e+10 | D19: 4.7737827e+09 | E19: 4.8707765e+09 | G19: 1.9392754e+09 | H19: 6.5537916e+08
A20: 0 | B20: IT | C20: 2.1159644e+11 | D20: 5.5783953e+10 | E20: 3.6794525e+10 | G20: 5.1018835e+10 | H20: 3.5835679e+10
A21: 0 | B21: LI | C21: 79960872 | D21: 23695145 | E21: 17673163 | G21: 13065987 | H21: 27023259
A22: 0 | B22: LT | C22: 8.5413707e+09 | D22: 2.0352728e+09 | E22: 4.6477433e+09 | F22: 1945882.9 | G22: 1.3133662e+10 | H22: 3.682413e+10
A23: 0 | B23: LU | C23: 5.5509197e+09 | D23: 2.6305587e+09 | E23: 9.0345769e+08 | G23: 1.5839722e+08 | H23: 5.7487031e+08
A24: 0 | B24: LV | C24: 7.2294819e+09 | D24: 1.438647e+09 | E24: 2.5990066e+09 | F24: 3057704.3 | G24: 8.0563569e+09 | H24: 5.0294596e+10
A25: 0 | B25: MD | C25: 5.605123e+09 | D25: 1.3833211e+09 | E25: 1.6182919e+09 | G25: 1.4122504e+09 | H25: 3.4629097e+09
A26: 0 | B26: ME | C26: 1.5157725e+09 | D26: 3.7488258e+08 | E26: 1.8944283e+08 | G26: 1.3515923e+08 | H26: 1.8993997e+09
A27: 0 | B27: MK | C27: 4.7996908e+09 | D27: 1.1888017e+09 | E27: 1.3549474e+09 | G27: 7.3383016e+08 | H27: 4.1491795e+08
A28: 0 | B28: NL | C28: 9.5300016e+10 | D28: 1.9265209e+10 | E28: 1.0286574e+10 | F28: 3.9737085e+10 | G28: 1.2558823e+10 | H28: 6.5718528e+09
A29: 0 | B29: NO | C29: 4.0194211e+10 | D29: 9.4038715e+09 | E29: 3.8603025e+09 | G29: 4.5280239e+09 | H29: 4.7564625e+09
A30: 0 | B30: PL | C30: 9.6095814e+10 | D30: 1.8900619e+10 | E30: 3.0156034e+10 | F30: 8.8307032e+08 | G30: 5.3870262e+10 | H30: 1.3167324e+11
A31: 0 | B31: PT | C31: 3.7367256e+10 | D31: 9.7777466e+09 | E31: 6.7178966e+09 | G31: 4.7176368e+09 | H31: 4.6541758e+09
A32: 0 | B32: RO | C32: 3.8572847e+10 | D32: 9.4241244e+09 | E32: 1.3976914e+10 | F32: 2.1604111e+10 | G32: 1.1339484e+10 | H32: 5.7844965e+10
A33: 0 | B33: RU | C33: 1.5810768e+11 | D33: 3.8793216e+10 | E33: 9.0632809e+10 | G33: 1.0534824e+11 | H33: 2.3285279e+11
A34: 0 | B34: SE | C34: 5.7554853e+10 | D34: 4.4883265e+09 | E34: 8.4311722e+09 | G34: 1.7913194e+10 | H34: 3.5584287e+10
A35: 0 | B35: SI | C35: 1.1790025e+10 | D35: 3.0859471e+09 | E35: 2.3349838e+09 | G35: 5.7381661e+09 | H35: 9.9885562e+09
A36: 0 | B36: SK | C36: 1.2780131e+10 | D36: 3.096644e+09 | E36: 4.0691924e+09 | F36: 7.0620128e+08 | G36: 2.5205881e+09 | H36: 2.3498613e+10
A37: 0 | B37: TR | C37: 1.1410953e+11 | D37: 2.7980099e+10 | E37: 1.1229698e+10 | G37: 5.0477639e+10 | H37: 1.3378092e+10
A38: 0 | B38: UA | C38: 7.4014817e+10 | D38: 1.8038036e+10 | E38: 2.2515409e+10 | G38: 3.5592575e+10 | H38: 7.7262588e+10
A39: 0 | B39: UK | C39: 3.3050775e+11 | D39: 7.5070057e+10 | E39: 2.6289449e+10 | F39: 3.2638265e+08 | G39: 4.8531517e+10 | H39: 3.7357669e+10
A40: 0 | B40: YU | C40: 2.0537374e+10 | D40: 5.0188134e+09 | E40: 2.1440241e+09 | F40: 1.3212523e+10 | G40: 2.0572184e+10 | H40: 9.3398794e+09

Sheet S01 Impact
A1: Difference from Baseline | O1: Type | P1: Air Pollution | Q1: Air Pollution | R1: Air Pollution | S1: Air Pollution | T1: Air Pollution | U1: Air Pollution | V1: Air Pollution | W1: Global Warming | X1: Global Warming | Y1: Global Warming | Z1: Global Warming | AA1: Global Warming | AB1: Global Warming | AC1: Global Warming | AD1: Accidents | AE1: Accidents | AF1: Accidents | AG1: Accidents | AH1: Noise | AI1: Noise | AJ1: Noise | AK1: Noise
A2: Scenario | B2: CountryCode | C2: vkm_petrol_Carpassenger | D2: vkm_diesel_Carpassenger | E2: vkm_hgv_Freight | F2: Total_IWW_TonKM | G2: PersonKM_RailPassenger | H2: TonKM_RailFreight | J2: _TYPE_ | K2: _FREQ_ | L2: personkm_Air | N2: Scenario | O2: CountryCode | P2: Car Petrol (€) | Q2: Car Diesel (€) | R2: HGV Diesel (€) | S2: Train Person (€) | T2: Train Freight (€) | U2: IWW (€) | V2: Air (€) | W2: Car Petrol (€) | X2: Car Diesel (€) | Y2: HGV Diesel (€) | Z2: Train Person (€) | AA2: Train Freight (€) | AB2: IWW (€) | AC2: Air (€) | AD2: Car (€) | AE2: HGV (€) | AF2: Train Person (€) | AG2: Train Freight (€) | AH2: Car (€) | AI2: HGV (€) | AJ2: Train Person (€) | AK2: Train Freight (€)
A3: =A45 -> 1 | B3: =IF(B45='S00 Impact'!B2,B45,0) -> AL | C3: =-(C45-'S00 Impact'!C2) -> 3436050.7 | D3: =-(D45-'S00 Impact'!D2) -> 852927.49 | E3: =-(E45-'S00 Impact'!E2) -> -146086.33 | F3: =-(F45-'S00 Impact'!F2) -> 0 | G3: =-(G45-'S00 Impact'!G2) -> -2224575.2 | H3: =-(H45-'S00 Impact'!H2) -> -53539.545 | J3: =J45 -> 0 | K3: =K45 -> 3153 | L3: =-(L45-'S00 Impact'!L2) -> 1.8203724e+09 | N3: =A3 -> 1 | O3: =B3 -> AL | P3: =C3*Road!D3/100 -> 3607.8533 | Q3: =D3*Road!E3/100 -> 2533.1946 | R3: =E3*Road!H3/100 -> -3314.6989 | S3: =G3*Rail!C3/100 -> -467.16078 | T3: =H3*Rail!D3/100 -> -10.172514 | U3: =F3*IWW!C3/100 -> 0 | W3: =C3*Road!F3/100 -> 32951.726 | X3: =D3*Road!G3/100 -> 8153.9868 | Y3: =E3*Road!I3/100 -> -6505.2244 | Z3: =G3*Rail!E3/100 -> -3381.3542 | AA3: =H3*Rail!F3/100 -> -46.579404 | AB3: =F3*IWW!D3/100 -> 0 | AD3: =(C3+D3)*Road!J3/100 -> 17713.48 | AE3: =E3*Road!L3/100 -> -1918.1136 | AF3: =G3*Rail!G3/100 -> -1156.7791 | AG3: =H3*Rail!I3/100 -> -14.455677 | AH3: =(C3+D3)*Road!K3/100 -> 14582.526 | AI3: =E3*Road!M3/100 -> -4308.086 | AJ3: =G3*Rail!H3/100 -> -3225.634 | AK3: =H3*Rail!J3/100 -> -20.880423
A4: =A46 -> 1 | B4: =IF(B46='S00 Impact'!B3,B46,0) -> AT | C4: =-(C46-'S00 Impact'!C3) -> 24900595 | D4: =-(D46-'S00 Impact'!D3) -> 8721566.5 | E4: =-(E46-'S00 Impact'!E3) -> -16192406 | F4: =-(F46-'S00 Impact'!F3) -> -5011676.6 | G4: =-(G46-'S00 Impact'!G3) -> -1.2845524e+08 | H4: =-(H46-'S00 Impact'!H3) -> -86278391 | N4: =A4 -> 1 | O4: =B4 -> AT | P4: =C4*Road!D4/100 -> 41085.982 | Q4: =D4*Road!E4/100 -> 56602.967 | R4: =E4*Road!H4/100 -> -839576.23 | S4: =G4*Rail!C4/100 -> -41105.676 | T4: =H4*Rail!D4/100 -> -9490.623 | U4: =F4*IWW!C4/100 -> -126344.37 | W4: =C4*Road!F4/100 -> 239045.71 | X4: =D4*Road!G4/100 -> 83290.96 | Y4: =E4*Road!I4/100 -> -721047.82 | Z4: =G4*Rail!E4/100 -> -195251.96 | AA4: =H4*Rail!F4/100 -> -75062.2 | AB4: =F4*IWW!D4/100 -> -13631.76 | AD4: =(C4+D4)*Road!J4/100 -> 168110.81 | AE4: =E4*Road!L4/100 -> -813506.45 | AF4: =G4*Rail!G4/100 -> -143869.87 | AG4: =H4*Rail!I4/100 -> -26746.301 | AH4: =(C4+D4)*Road!K4/100 -> 239726.01 | AI4: =E4*Road!M4/100 -> -762176.53 | AJ4: =G4*Rail!H4/100 -> -146438.97 | AK4: =H4*Rail!J4/100 -> -121652.53
A5: =A47 -> 1 | B5: =IF(B47='S00 Impact'!B4,B47,0) -> BA | C5: =-(C47-'S00 Impact'!C4) -> 9108102.1 | D5: =-(D47-'S00 Impact'!D4) -> 2118000.4 | E5: =-(E47-'S00 Impact'!E4) -> -460906.8 | F5: =-(F47-'S00 Impact'!F4) -> -4170066.3 | G5: =-(G47-'S00 Impact'!G4) -> 3835422.8 | H5: =-(H47-'S00 Impact'!H4) -> -1636312.3 | N5: =A5 -> 1 | O5: =B5 -> BA | P5: =C5*Road!D5/100 -> 8197.2919 | Q5: =D5*Road!E5/100 -> 5422.081 | R5: =E5*Road!H5/100 -> -8987.6825 | S5: =G5*Rail!C5/100 -> 2991.6298 | T5: =H5*Rail!D5/100 -> -736.34054 | U5: =F5*IWW!C5/100 -> -78230.444 | W5: =C5*Road!F5/100 -> 87346.7 | X5: =D5*Road!G5/100 -> 20248.084 | Y5: =E5*Road!I5/100 -> -20524.18 | Z5: =G5*Rail!E5/100 -> 5829.8427 | AA5: =H5*Rail!F5/100 -> -1423.5917 | AB5: =F5*IWW!D5/100 -> -11342.58 | AD5: =(C5+D5)*Road!J5/100 -> 39852.664 | AE5: =E5*Road!L5/100 -> -5199.0287 | AF5: =G5*Rail!G5/100 -> 2838.2129 | AG5: =H5*Rail!I5/100 -> -441.80433 | AH5: =(C5+D5)*Road!K5/100 -> 32892.48 | AI5: =E5*Road!M5/100 -> -11679.378 | AJ5: =G5*Rail!H5/100 -> 5139.4666 | AK5: =H5*Rail!J5/100 -> -621.79868
A6: =A48 -> 1 | B6: =IF(B48='S00 Impact'!B5,B48,0) -> BE | C6: =-(C48-'S00 Impact'!C5) -> 7574832 | D6: =-(D48-'S00 Impact'!D5) -> -417678.53 | E6: =-(E48-'S00 Impact'!E5) -> -5325689.8 | F6: =-(F48-'S00 Impact'!F5) -> 2932680.9 | G6: =-(G48-'S00 Impact'!G5) -> -41281184 | H6: =-(H48-'S00 Impact'!H5) -> 3236667.1 | N6: =A6 -> 1 | O6: =B6 -> BE | P6: =C6*Road!D6/100 -> 12195.48 | Q6: =D6*Road!E6/100 -> -1929.6748 | R6: =E6*Road!H6/100 -> -184641.67 | S6: =G6*Rail!C6/100 -> -151089.13 | T6: =H6*Rail!D6/100 -> 6829.3675 | U6: =F6*IWW!C6/100 -> 65574.746 | W6: =C6*Road!F6/100 -> 72718.387 | X6: =D6*Road!G6/100 -> -3988.8299 | Y6: =E6*Road!I6/100 -> -237152.97 | Z6: =G6*Rail!E6/100 -> -62747.4 | AA6: =H6*Rail!F6/100 -> 2815.9004 | AB6: =F6*IWW!D6/100 -> 7976.8921 | AD6: =(C6+D6)*Road!J6/100 -> 41010.489 | AE6: =E6*Road!L6/100 -> -518136.36 | AF6: =G6*Rail!G6/100 -> -29309.641 | AG6: =H6*Rail!I6/100 -> 809.16677 | AH6: =(C6+D6)*Road!K6/100 -> 47094.07 | AI6: =E6*Road!M6/100 -> -231401.22 | AJ6: =G6*Rail!H6/100 -> -16512.474 | AK6: =H6*Rail!J6/100 -> 2136.2003
A7: =A49 -> 1 | B7: =IF(B49='S00 Impact'!B6,B49,0) -> BG | C7: =-(C49-'S00 Impact'!C6) -> -412367.81 | D7: =-(D49-'S00 Impact'!D6) -> -996611.55 | E7: =-(E49-'S00 Impact'!E6) -> -1665044.6 | F7: =-(F49-'S00 Impact'!F6) -> -1347452.4 | G7: =-(G49-'S00 Impact'!G6) -> -5180360.8 | H7: =-(H49-'S00 Impact'!H6) -> -10124819 | N7: =A7 -> 1 | O7: =B7 -> BG | P7: =C7*Road!D7/100 -> -329.89425 | Q7: =D7*Road!E7/100 -> -2262.3082 | R7: =E7*Road!H7/100 -> -28888.524 | S7: =G7*Rail!C7/100 -> -2434.7696 | T7: =H7*Rail!D7/100 -> -2733.7011 | U7: =F7*IWW!C7/100 -> -6333.0265 | W7: =C7*Road!F7/100 -> -3954.6073 | X7: =D7*Road!G7/100 -> -9527.6064 | Y7: =E7*Road!I7/100 -> -74144.437 | Z7: =G7*Rail!E7/100 -> -7874.1484 | AA7: =H7*Rail!F7/100 -> -8808.5924 | AB7: =F7*IWW!D7/100 -> -3665.0706 | AD7: =(C7+D7)*Road!J7/100 -> -4438.285 | AE7: =E7*Road!L7/100 -> -16717.048 | AF7: =G7*Rail!G7/100 -> -4403.3067 | AG7: =H7*Rail!I7/100 -> -2733.7011 | AH7: =(C7+D7)*Road!K7/100 -> -3663.3463 | AI7: =E7*Road!M7/100 -> -37546.756 | AJ7: =G7*Rail!H7/100 -> -11137.776 | AK7: =H7*Rail!J7/100 -> -3037.4457
A8: =A50 -> 1 | B8: =IF(B50='S00 Impact'!B7,B50,0) -> BY | C8: =-(C50-'S00 Impact'!C7) -> 15745076 | D8: =-(D50-'S00 Impact'!D7) -> 3926120 | E8: =-(E50-'S00 Impact'!E7) -> 27352081 | F8: =-(F50-'S00 Impact'!F7) -> 0 | G8: =-(G50-'S00 Impact'!G7) -> 84498665 | H8: =-(H50-'S00 Impact'!H7) -> -98858064 | N8: =A8 -> 1 | O8: =B8 -> BY | P8: =C8*Road!D8/100 -> 15902.527 | Q8: =D8*Road!E8/100 -> 11189.442 | R8: =E8*Road!H8/100 -> 595454.8 | S8: =G8*Rail!C8/100 -> 62529.012 | T8: =H8*Rail!D8/100 -> -43497.548 | U8: =F8*IWW!C8/100 -> 0 | W8: =C8*Road!F8/100 -> 150995.28 | X8: =D8*Road!G8/100 -> 37533.707 | Y8: =E8*Road!I8/100 -> 1217988.2 | Z8: =G8*Rail!E8/100 -> 128437.97 | AA8: =H8*Rail!F8/100 -> -86006.515 | AB8: =F8*IWW!D8/100 -> 0 | AD8: =(C8+D8)*Road!J8/100 -> 77897.936 | AE8: =E8*Road!L8/100 -> 344362.7 | AF8: =G8*Rail!G8/100 -> 59994.052 | AG8: =H8*Rail!I8/100 -> -26691.677 | AH8: =(C8+D8)*Road!K8/100 -> 64324.811 | AI8: =E8*Road!M8/100 -> 773790.37 | AJ8: =G8*Rail!H8/100 -> 26194.586 | AK8: =H8*Rail!J8/100 -> -33611.742
A9: =A51 -> 1 | B9: =IF(B51='S00 Impact'!B8,B51,0) -> CH | C9: =-(C51-'S00 Impact'!C8) -> 1850019.3 | D9: =-(D51-'S00 Impact'!D8) -> -563102.88 | E9: =-(E51-'S00 Impact'!E8) -> -325735.81 | F9: =-(F51-'S00 Impact'!F8) -> -28417.494 | G9: =-(G51-'S00 Impact'!G8) -> -43362143 | H9: =-(H51-'S00 Impact'!H8) -> 63328448 | N9: =A9 -> 1 | O9: =B9 -> CH | P9: =C9*Road!D9/100 -> 5716.5597 | Q9: =D9*Road!E9/100 -> -4915.8881 | R9: =E9*Road!H9/100 -> -21700.52 | S9: =G9*Rail!C9/100 -> -17344.857 | T9: =H9*Rail!D9/100 -> 14565.543 | U9: =F9*IWW!C9/100 -> -533.11219 | W9: =C9*Road!F9/100 -> 17741.685 | X9: =D9*Road!G9/100 -> -5383.2635 | Y9: =E9*Road!I9/100 -> -14505.016 | Z9: =G9*Rail!E9/100 -> -65910.457 | AA9: =H9*Rail!F9/100 -> 55095.75 | AB9: =F9*IWW!D9/100 -> -77.295584 | AD9: =(C9+D9)*Road!J9/100 -> 15584.558 | AE9: =E9*Road!L9/100 -> -12557.116 | AF9: =G9*Rail!G9/100 -> -59839.757 | AG9: =H9*Rail!I9/100 -> 8865.9827 | AH9: =(C9+D9)*Road!K9/100 -> 12869.164 | AI9: =E9*Road!M9/100 -> -28202.207 | AJ9: =G9*Rail!H9/100 -> -95396.714 | AK9: =H9*Rail!J9/100 -> 37363.784
A10: =A52 -> 1 | B10: =IF(B52='S00 Impact'!B9,B52,0) -> CZ | C10: =-(C52-'S00 Impact'!C9) -> 12752685 | D10: =-(D52-'S00 Impact'!D9) -> 2284276.8 | E10: =-(E52-'S00 Impact'!E9) -> -7910937.6 | F10: =-(F52-'S00 Impact'!F9) -> -9640.8314 | G10: =-(G52-'S00 Impact'!G9) -> -22446281 | H10: =-(H52-'S00 Impact'!H9) -> -41236607 | N10: =A10 -> 1 | O10: =B10 -> CZ | P10: =C10*Road!D10/100 -> 18491.393 | Q10: =D10*Road!E10/100 -> 9456.906 | R10: =E10*Road!H10/100 -> -250143.85 | S10: =G10*Rail!C10/100 -> -18181.488 | T10: =H10*Rail!D10/100 -> -17731.741 | U10: =F10*IWW!C10/100 -> -180.862 | W10: =C10*Road!F10/100 -> 122425.78 | X10: =D10*Road!G10/100 -> 21814.844 | Y10: =E10*Road!I10/100 -> -352274.05 | Z10: =G10*Rail!E10/100 -> -34118.347 | AA10: =H10*Rail!F10/100 -> -35875.848 | AB10: =F10*IWW!D10/100 -> -26.223061 | AD10: =(C10+D10)*Road!J10/100 -> 33382.055 | AE10: =E10*Road!L10/100 -> -154025.95 | AF10: =G10*Rail!G10/100 -> -12345.455 | AG10: =H10*Rail!I10/100 -> -11546.25 | AH10: =(C10+D10)*Road!K10/100 -> 74282.591 | AI10: =E10*Road!M10/100 -> -382968.49 | AJ10: =G10*Rail!H10/100 -> -22446.281 | AK10: =H10*Rail!J10/100 -> -52782.857
A11: =A53 -> 1 | B11: =IF(B53='S00 Impact'!B10,B53,0) -> DE | C11: =-(C53-'S00 Impact'!C10) -> 1.2026586e+08 | D11: =-(D53-'S00 Impact'!D10) -> 20035440 | E11: =-(E53-'S00 Impact'!E10) -> 5792555.8 | F11: =-(F53-'S00 Impact'!F10) -> -23129189 | G11: =-(G53-'S00 Impact'!G10) -> -4.0388373e+08 | H11: =-(H53-'S00 Impact'!H10) -> 2.1627852e+08 | N11: =A11 -> 1 | O11: =B11 -> DE | P11: =C11*Road!D11/100 -> 177993.47 | Q11: =D11*Road!E11/100 -> 122616.89 | R11: =E11*Road!H11/100 -> 285225.45 | S11: =G11*Rail!C11/100 -> -141359.31 | T11: =H11*Rail!D11/100 -> 43255.703 | U11: =F11*IWW!C11/100 -> -561808.01 | W11: =C11*Road!F11/100 -> 1154552.2 | X11: =D11*Road!G11/100 -> 191338.45 | Y11: =E11*Road!I11/100 -> 257942.51 | Z11: =G11*Rail!E11/100 -> -613903.28 | AA11: =H11*Rail!F11/100 -> 188162.31 | AB11: =F11*IWW!D11/100 -> -62911.395 | AD11: =(C11+D11)*Road!J11/100 -> 533144.93 | AE11: =E11*Road!L11/100 -> 223187.17 | AF11: =G11*Rail!G11/100 -> -343301.17 | AG11: =H11*Rail!I11/100 -> 58395.199 | AH11: =(C11+D11)*Road!K11/100 -> 819359.58 | AI11: =E11*Road!M11/100 -> 223360.95 | AJ11: =G11*Rail!H11/100 -> -577553.74 | AK11: =H11*Rail!J11/100 -> 82185.836
A12: =A54 -> 1 | B12: =IF(B54='S00 Impact'!B11,B54,0) -> DK | C12: =-(C54-'S00 Impact'!C11) -> -56184322 | D12: =-(D54-'S00 Impact'!D11) -> -10097752 | E12: =-(E54-'S00 Impact'!E11) -> -14845245 | F12: =-(F54-'S00 Impact'!F11) -> 0 | G12: =-(G54-'S00 Impact'!G11) -> -19383865 | H12: =-(H54-'S00 Impact'!H11) -> -42.930384 | N12: =A12 -> 1 | O12: =B12 -> DK | P12: =C12*Road!D12/100 -> -77534.365 | Q12: =D12*Road!E12/100 -> -36856.797 | R12: =E12*Road!H12/100 -> -410025.65 | S12: =G12*Rail!C12/100 -> -8916.5778 | T12: =H12*Rail!D12/100 -> -0.013308419 | U12: =F12*IWW!C12/100 -> 0 | W12: =C12*Road!F12/100 -> -539369.5 | X12: =D12*Road!G12/100 -> -96433.536 | Y12: =E12*Road!I12/100 -> -661058.74 | Z12: =G12*Rail!E12/100 -> -29463.475 | AA12: =H12*Rail!F12/100 -> -0.037349434 | AB12: =F12*IWW!D12/100 -> 0 | AD12: =(C12+D12)*Road!J12/100 -> -258500.09 | AE12: =E12*Road!L12/100 -> -531905.11 | AF12: =G12*Rail!G12/100 -> -11048.803 | AG12: =H12*Rail!I12/100 -> -0.013308419 | AH12: =(C12+D12)*Road!K12/100 -> -568700.2 | AI12: =E12*Road!M12/100 -> -840686.2 | AJ12: =G12*Rail!H12/100 -> -10273.448 | AK12: =H12*Rail!J12/100 -> -0.054950892
A13: =A55 -> 1 | B13: =IF(B55='S00 Impact'!B12,B55,0) -> EE | C13: =-(C55-'S00 Impact'!C12) -> 4151031.9 | D13: =-(D55-'S00 Impact'!D12) -> 670432.58 | E13: =-(E55-'S00 Impact'!E12) -> -544644.72 | F13: =-(F55-'S00 Impact'!F12) -> 0 | G13: =-(G55-'S00 Impact'!G12) -> 398593.28 | H13: =-(H55-'S00 Impact'!H12) -> 32445610 | N13: =A13 -> 1 | O13: =B13 -> EE | P13: =C13*Road!D13/100 -> 8592.636 | Q13: =D13*Road!E13/100 -> 3948.8479 | R13: =E13*Road!H13/100 -> -24509.012 | S13: =G13*Rail!C13/100 -> 1267.5266 | T13: =H13*Rail!D13/100 -> 59375.466 | U13: =F13*IWW!C13/100 -> 0 | W13: =C13*Road!F13/100 -> 39849.906 | X13: =D13*Road!G13/100 -> 6402.6312 | Y13: =E13*Road!I13/100 -> -24253.029 | Z13: =G13*Rail!E13/100 -> 605.86179 | AA13: =H13*Rail!F13/100 -> 28227.681 | AB13: =F13*IWW!D13/100 -> 0 | AD13: =(C13+D13)*Road!J13/100 -> 10848.295 | AE13: =E13*Road!L13/100 -> -15092.105 | AF13: =G13*Rail!G13/100 -> 283.00123 | AG13: =H13*Rail!I13/100 -> 11031.507 | AH13: =(C13+D13)*Road!K13/100 -> 33894.895 | AI13: =E13*Road!M13/100 -> -37515.128 | AJ13: =G13*Rail!H13/100 -> 151.46545 | AK13: =H13*Rail!J13/100 -> 64242.308
A14: =A56 -> 1 | B14: =IF(B56='S00 Impact'!B13,B56,0) -> ES | C14: =-(C56-'S00 Impact'!C13) -> -67647316 | D14: =-(D56-'S00 Impact'!D13) -> -42966739 | E14: =-(E56-'S00 Impact'!E13) -> -1694350.6 | F14: =-(F56-'S00 Impact'!F13) -> 0 | G14: =-(G56-'S00 Impact'!G13) -> 60637428 | H14: =-(H56-'S00 Impact'!H13) -> 1055334 | N14: =A14 -> 1 | O14: =B14 -> ES | P14: =C14*Road!D14/100 -> -115000.44 | Q14: =D14*Road!E14/100 -> -146516.58 | R14: =E14*Road!H14/100 -> -41223.55 | S14: =G14*Rail!C14/100 -> 20010.351 | T14: =H14*Rail!D14/100 -> 200.51346 | U14: =F14*IWW!C14/100 -> 0 | W14: =C14*Road!F14/100 -> -649414.23 | X14: =D14*Road!G14/100 -> -410332.35 | Y14: =E14*Road!I14/100 -> -75449.432 | Z14: =G14*Rail!E14/100 -> 92168.89 | AA14: =H14*Rail!F14/100 -> 918.1406 | AB14: =F14*IWW!D14/100 -> 0 | AD14: =(C14+D14)*Road!J14/100 -> -498869.39 | AE14: =E14*Road!L14/100 -> -8403.979 | AF14: =G14*Rail!G14/100 -> 38807.954 | AG14: =H14*Rail!I14/100 -> 284.94019 | AH14: =(C14+D14)*Road!K14/100 -> -634924.67 | AI14: =E14*Road!M14/100 -> -64198.944 | AJ14: =G14*Rail!H14/100 -> 98839.007 | AK14: =H14*Rail!J14/100 -> 306.04687
A15: =A57 -> 1 | B15: =IF(B57='S00 Impact'!B14,B57,0) -> FI | C15: =-(C57-'S00 Impact'!C14) -> 24519108 | D15: =-(D57-'S00 Impact'!D14) -> 4529216.5 | E15: =-(E57-'S00 Impact'!E14) -> -2258745 | F15: =-(F57-'S00 Impact'!F14) -> 0 | G15: =-(G57-'S00 Impact'!G14) -> -30883793 | H15: =-(H57-'S00 Impact'!H14) -> -7269170.8 | N15: =A15 -> 1 | O15: =B15 -> FI | P15: =C15*Road!D15/100 -> 47076.688 | Q15: =D15*Road!E15/100 -> 24729.522 | R15: =E15*Road!H15/100 -> -94167.08 | S15: =G15*Rail!C15/100 -> -11427.003 | T15: =H15*Rail!D15/100 -> -2544.2098 | U15: =F15*IWW!C15/100 -> 0 | W15: =C15*Road!F15/100 -> 235383.44 | X15: =D15*Road!G15/100 -> 43254.017 | Y15: =E15*Road!I15/100 -> -100581.92 | Z15: =G15*Rail!E15/100 -> -46943.366 | AA15: =H15*Rail!F15/100 -> -6324.1786 | AB15: =F15*IWW!D15/100 -> 0 | AD15: =(C15+D15)*Road!J15/100 -> 131298.43 | AE15: =E15*Road!L15/100 -> -57981.985 | AF15: =G15*Rail!G15/100 -> -28721.928 | AG15: =H15*Rail!I15/100 -> -3125.7434 | AH15: =(C15+D15)*Road!K15/100 -> 189104.59 | AI15: =E15*Road!M15/100 -> -144153.11 | AJ15: =G15*Rail!H15/100 -> -34281.01 | AK15: =H15*Rail!J15/100 -> -9667.9972
... A41: =A83 -> 1 | B41: =IF(B83='S00 Impact'!B40,B83,0) -> YU | C41: =-(C83-'S00 Impact'!C40) -> 12164320 | D41: =-(D83-'S00 Impact'!D40) -> 1546728.3 | E41: =-(E83-'S00 Impact'!E40) -> -1075056.2 | F41: =-(F83-'S00 Impact'!F40) -> -8061478.1 | G41: =-(G83-'S00 Impact'!G40) -> 35107405 | H41: =-(H83-'S00 Impact'!H40) -> 2417812.6 | N41: =A41 -> 1 | O41: =B41 -> YU | P41: =C41*Road!D41/100 -> 10947.888 | Q41: =D41*Road!E41/100 -> 3959.6245 | R41: =E41*Road!H41/100 -> -20963.595 | S41: =G41*Rail!C41/100 -> 14745.11 | T41: =H41*Rail!D41/100 -> 580.27503 | U41: =F41*IWW!C41/100 -> -102542 | W41: =C41*Road!F41/100 -> 116655.83 | X41: =D41*Road!G41/100 -> 14786.723 | Y41: =E41*Road!I41/100 -> -47872.251 | Z41: =G41*Rail!E41/100 -> 53363.256 | AA41: =H41*Rail!F41/100 -> 2103.497 | AB41: =F41*IWW!D41/100 -> -21927.22 | AD41: =(C41+D41)*Road!J41/100 -> 48674.221 | AE41: =E41*Road!L41/100 -> -12126.633 | AF41: =G41*Rail!G41/100 -> 24926.258 | AG41: =H41*Rail!I41/100 -> 652.80941 | AH41: =(C41+D41)*Road!K41/100 -> 40173.371 | AI41: =E41*Road!M41/100 -> -27241.923 | AJ41: =G41*Rail!H41/100 -> 13340.814 | AK41: =H41*Rail!J41/100 -> 1184.7282
N42: =N41 -> 1 | O42: Total | P42: =SUM(P3:P41) -> 287276.58 | Q42: =SUM(Q3:Q41) -> 26367.327 | R42: =SUM(R3:R41) -> -3799293.8 | S42: =SUM(S3:S41) -> -1349271.1 | T42: =SUM(T3:T41) -> -123301.71 | U42: =SUM(U3:U41) -> -1263349.1 | V42: =L3*Air!C3/100 -> 12524162 | W42: =SUM(W3:W41) -> 4328270 | X42: =SUM(X3:X41) -> 444928.38 | Y42: =SUM(Y3:Y41) -> -5621466.5 | Z42: =SUM(Z3:Z41) -> -3731336.3 | AA42: =SUM(AA3:AA41) -> 164826.11 | AB42: =SUM(AB3:AB41) -> -171277.5 | AC42: =L3*Air!D3/100 -> 9083658.1 | AD42: =SUM(AD3:AD41) -> 749663.74 | AE42: =SUM(AE3:AE41) -> -2091332 | AF42: =SUM(AF3:AF41) -> -1893173.4 | AG42: =SUM(AG3:AG41) -> 31170.618 | AH42: =SUM(AH3:AH41) -> 72036.384 | AI42: =SUM(AI3:AI41) -> -2562343.4 | AJ42: =SUM(AJ3:AJ41) -> -2650529.7 | AK42: =SUM(AK3:AK41) -> -112698.51 | AL42: =SUM(P42:AK42) -> 2342986.1
V43: =SUM(P42:V42) -> 6302590.1 | AC43: =SUM(W42:AC42) -> 4497602.3 | AG43: =SUM(AD42:AG42) -> -3203671.1 | AK43: =SUM(AH42:AK42) -> -5253535.2
A44: Scenario | B44: CountryCode | C44: vkm_petrol_Carpassenger | D44: vkm_diesel_Carpassenger | E44: vkm_hgv_Freight | F44: Total_IWW_TonKM | G44: PersonKM_RailPassenger | H44: TonKM_RailFreight | J44: _TYPE_ | K44: _FREQ_ | L44: personkm_Air
A45: 1 | B45: AL | C45: 2.1946305e+09 | D45: 5.4290401e+08 | E45: 7.7736729e+08 | G45: 1.2919561e+08 | H45: 5.9563205e+08 | J45: 0 | K45: 3153 | L45: 8.3747343e+11
A46: 1 | B46: AT | C46: 4.306107e+10 | D46: 2.7041061e+10 | E46: 6.9015111e+09 | F46: 7.1114365e+09 | G46: 1.59888e+10 | H46: 2.4846053e+10
A47: 1 | B47: BA | C47: 5.0186891e+09 | D47: 1.2314642e+09 | E47: 8.4395451e+08 | F47: 7.4288782e+08 | G47: 5.9616295e+08 | H47: 1.2100905e+09
A48: 1 | B48: BE | C48: 4.2890233e+10 | D48: 3.2554207e+10 | E48: 8.4131374e+09 | F48: 9.585723e+09 | G48: 1.4194191e+10 | H48: 9.8118004e+09
A49: 1 | B49: BG | C49: 2.7971831e+10 | D49: 6.8361139e+09 | E49: 3.8423632e+09 | F49: 2.1019819e+09 | G49: 1.7015141e+10 | H49: 2.3019948e+10
A50: 1 | B50: BY | C50: 1.9217264e+10 | D50: 4.6324636e+09 | E50: 1.0407868e+10 | G50: 7.6271136e+09 | H50: 2.7050324e+10
A51: 1 | B51: CH | C51: 3.9944687e+10 | D51: 5.7135003e+09 | E51: 3.6438324e+09 | F51: 38969820 | G51: 1.1722333e+10 | H51: 1.1493976e+10
A52: 1 | B52: CZ | C52: 3.1717751e+10 | D52: 6.8882176e+09 | E52: 8.5555989e+09 | F52: 45311807 | G52: 9.3832196e+09 | H52: 3.5408529e+10
A53: 1 | B53: DE | C53: 3.7988934e+11 | D53: 8.8651875e+10 | E53: 4.6521887e+10 | F53: 7.5707877e+10 | G53: 1.1530356e+11 | H53: 1.0989409e+11
A54: 1 | B54: DK | C54: 3.7300951e+10 | D54: 3.8759444e+09 | E54: 7.2575758e+09 | G54: 6.4041322e+09 | H54: 3.3950105e+09
A55: 1 | B55: EE | C55: 3.3524979e+09 | D55: 6.0897248e+08 | E55: 1.8205132e+09 | G55: 2.8984304e+08 | H55: 3.0963131e+10
A56: 1 | B56: ES | C56: 1.7617341e+11 | D56: 9.4508052e+10 | E56: 4.8190827e+10 | G56: 2.9449567e+10 | H56: 2.4315302e+10
A57: 1 | B57: FI | C57: 2.9635967e+10 | D57: 4.325075e+09 | E57: 5.6562276e+09 | G57: 7.685976e+09 | H57: 2.211241e+10
A58: 1 | B58: FR | C58: 2.4538014e+11 | D58: 1.6776506e+11 | E58: 4.4052248e+10 | F58: 1.202358e+10 | G58: 9.5228413e+10 | H58: 5.5772116e+10
A59: 1 | B59: GR | C59: 2.7367376e+10 | D59: 6.7750061e+09 | E59: 6.2801838e+09 | G59: 2.9098501e+09 | H59: 1.4354068e+09
A60: 1 | B60: HR | C60: 2.2442137e+10 | D60: 5.5764745e+09 | E60: 2.6739356e+09 | F60: 3.1370498e+08 | G60: 9.2550823e+09 | H60: 7.5194226e+09
A61: 1 | B61: HU | C61: 2.9564689e+10 | D61: 6.0746475e+09 | E61: 5.3926668e+09 | F61: 1.1189849e+10 | G61: 1.5314321e+10 | H61: 2.372996e+10
A62: 1 | B62: IE | C62: 2.7595517e+10 | D62: 4.7750097e+09 | E62: 4.8659036e+09 | G62: 1.9408054e+09 | H62: 6.5536353e+08
A63: 1 | B63: IT | C63: 2.1149886e+11 | D63: 5.5750632e+10 | E63: 3.6796672e+10 | G63: 5.0980708e+10 | H63: 3.5958865e+10
A64: 1 | B64: LI | C64: 79887940 | D64: 23501476 | E64: 18047856 | G64: 15599827 | H64: 29501252
A65: 1 | B65: LT | C65: 8.537557e+09 | D65: 2.0340216e+09 | E65: 4.6497686e+09 | F65: 1945882.9 | G65: 1.3299707e+10 | H65: 3.6778794e+10
...

Sheet S10 Impact
A1: Difference from Baseline | O1: Type | P1: Air Pollution | Q1: Air Pollution | R1: Air Pollution | S1: Air Pollution | T1: Air Pollution | U1: Air Pollution | V1: Air Pollution | W1: Global Warming | X1: Global Warming | Y1: Global Warming | Z1: Global Warming | AA1: Global Warming | AB1: Global Warming | AC1: Global Warming | AD1: Accidents | AE1: Accidents | AF1: Accidents | AG1: Accidents | AH1: Noise | AI1: Noise | AJ1: Noise | AK1: Noise
A2: Scenario | B2: CountryCode | C2: vkm_petrol_Carpassenger | D2: vkm_diesel_Carpassenger | E2: vkm_hgv_Freight | F2: Total_IWW_TonKM | G2: PersonKM_RailPassenger | H2: TonKM_RailFreight | J2: _TYPE_ | K2: _FREQ_ | L2: personkm_Air | N2: Scenario | O2: CountryCode | P2: Car Petrol (€) | Q2: Car Diesel (€) | R2: HGV Diesel (€) | S2: Train Person (€) | T2: Train Freight (€) | U2: IWW (€) | V2: Air (€) | W2: Car Petrol (€) | X2: Car Diesel (€) | Y2: HGV Diesel (€) | Z2: Train Person (€) | AA2: Train Freight (€) | AB2: IWW (€) | AC2: Air (€) | AD2: Car (€) | AE2: HGV (€) | AF2: Train Person (€) | AG2: Train Freight (€) | AH2: Car (€) | AI2: HGV (€) | AJ2: Train Person (€) | AK2: Train Freight (€)
A3: =A45 -> 10 | B3: =IF(B45='S00 Impact'!B2,B45,0) -> AL | C3: =-(C45-'S00 Impact'!C2) -> 9255162.2 | D3: =-(D45-'S00 Impact'!D2) -> 2143899.3 | E3: =-(E45-'S00 Impact'!E2) -> -355285.61 | F3: =-(F45-'S00 Impact'!F2) -> 0 | G3: =-(G45-'S00 Impact'!G2) -> -433334.2 | H3: =-(H45-'S00 Impact'!H2) -> -1685061.9 | J3: =J45 -> 0 | K3: =K45 -> 3153 | L3: =-(L45-'S00 Impact'!L2) -> 1.4384403e+09 | N3: =A3 -> 10 | O3: =B3 -> AL | P3: =C3*Road!D3/100 -> 9717.9203 | Q3: =D3*Road!E3/100 -> 6367.3809 | R3: =E3*Road!H3/100 -> -8061.4304 | S3: =G3*Rail!C3/100 -> -91.000182 | T3: =H3*Rail!D3/100 -> -320.16176 | U3: =F3*IWW!C3/100 -> 0 | W3: =C3*Road!F3/100 -> 88757.006 | X3: =D3*Road!G3/100 -> 20495.677 | Y3: =E3*Road!I3/100 -> -15820.868 | Z3: =G3*Rail!E3/100 -> -658.66799 | AA3: =H3*Rail!F3/100 -> -1466.0038 | AB3: =F3*IWW!D3/100 -> 0 | AD3: =(C3+D3)*Road!J3/100 -> 47078.124 | AE3: =E3*Road!L3/100 -> -4664.9 | AF3: =G3*Rail!G3/100 -> -225.33378 | AG3: =H3*Rail!I3/100 -> -454.96671 | AH3: =(C3+D3)*Road!K3/100 -> 38756.809 | AI3: =E3*Road!M3/100 -> -10477.373 | AJ3: =G3*Rail!H3/100 -> -628.33459 | AK3: =H3*Rail!J3/100 -> -657.17414
A4: =A46 -> 10 | B4: =IF(B46='S00 Impact'!B3,B46,0) -> AT | C4: =-(C46-'S00 Impact'!C3) -> -57014963 | D4: =-(D46-'S00 Impact'!D3) -> -13069218 | E4: =-(E46-'S00 Impact'!E3) -> -30358889 | F4: =-(F46-'S00 Impact'!F3) -> -2630514.2 | G4: =-(G46-'S00 Impact'!G3) -> -4.0385122e+08 | H4: =-(H46-'S00 Impact'!H3) -> -44195056 | N4: =A4 -> 10 | O4: =B4 -> AT | P4: =C4*Road!D4/100 -> -94074.689 | Q4: =D4*Road!E4/100 -> -84819.224 | R4: =E4*Road!H4/100 -> -1574108.4 | S4: =G4*Rail!C4/100 -> -129232.39 | T4: =H4*Rail!D4/100 -> -4861.4561 | U4: =F4*IWW!C4/100 -> -66315.262 | W4: =C4*Road!F4/100 -> -547343.65 | X4: =D4*Road!G4/100 -> -124811.03 | Y4: =E4*Road!I4/100 -> -1351881.3 | Z4: =G4*Rail!E4/100 -> -613853.85 | AA4: =H4*Rail!F4/100 -> -38449.699 | AB4: =F4*IWW!D4/100 -> -7154.9985 | AD4: =(C4+D4)*Road!J4/100 -> -350420.9 | AE4: =E4*Road!L4/100 -> -1525230.6 | AF4: =G4*Rail!G4/100 -> -452313.36 | AG4: =H4*Rail!I4/100 -> -13700.467 | AH4: =(C4+D4)*Road!K4/100 -> -499700.21 | AI4: =E4*Road!M4/100 -> -1428992.9 | AJ4: =G4*Rail!H4/100 -> -460390.39 | AK4: =H4*Rail!J4/100 -> -62315.029
A5: =A47 -> 10 | B5: =IF(B47='S00 Impact'!B4,B47,0) -> BA | C5: =-(C47-'S00 Impact'!C4) -> 84872859 | D5: =-(D47-'S00 Impact'!D4) -> 21485350 | E5: =-(E47-'S00 Impact'!E4) -> -29017172 | F5: =-(F47-'S00 Impact'!F4) -> -858931.97 | G5: =-(G47-'S00 Impact'!G4) -> 1740137.1 | H5: =-(H47-'S00 Impact'!H4) -> -1691217 | N5: =A5 -> 10 | O5: =B5 -> BA | P5: =C5*Road!D5/100 -> 76385.574 | Q5: =D5*Road!E5/100 -> 55002.496 | R5: =E5*Road!H5/100 -> -565834.86 | S5: =G5*Rail!C5/100 -> 1357.3069 | T5: =H5*Rail!D5/100 -> -761.04765 | U5: =F5*IWW!C5/100 -> -16113.564 | W5: =C5*Road!F5/100 -> 813930.72 | X5: =D5*Road!G5/100 -> 205399.95 | Y5: =E5*Road!I5/100 -> -1292134.7 | Z5: =G5*Rail!E5/100 -> 2645.0084 | AA5: =H5*Rail!F5/100 -> -1471.3588 | AB5: =F5*IWW!D5/100 -> -2336.2949 | AD5: =(C5+D5)*Road!J5/100 -> 377571.64 | AE5: =E5*Road!L5/100 -> -327313.7 | AF5: =G5*Rail!G5/100 -> 1287.7014 | AG5: =H5*Rail!I5/100 -> -456.62859 | AH5: =(C5+D5)*Road!K5/100 -> 311629.55 | AI5: =E5*Road!M5/100 -> -735295.14 | AJ5: =G5*Rail!H5/100 -> 2331.7837 | AK5: =H5*Rail!J5/100 -> -642.66246
A6: =A48 -> 10 | B6: =IF(B48='S00 Impact'!B5,B48,0) -> BE | C6: =-(C48-'S00 Impact'!C5) -> 12815894 | D6: =-(D48-'S00 Impact'!D5) -> 2188291.6 | E6: =-(E48-'S00 Impact'!E5) -> 100125.86 | F6: =-(F48-'S00 Impact'!F5) -> 7455332 | G6: =-(G48-'S00 Impact'!G5) -> -9214287.4 | H6: =-(H48-'S00 Impact'!H5) -> 4749826.3 | N6: =A6 -> 10 | O6: =B6 -> BE | P6: =C6*Road!D6/100 -> 20633.589 | Q6: =D6*Road!E6/100 -> 10109.907 | R6: =E6*Road!H6/100 -> 3471.3637 | S6: =G6*Rail!C6/100 -> -33724.292 | T6: =H6*Rail!D6/100 -> 10022.133 | U6: =F6*IWW!C6/100 -> 166701.22 | W6: =C6*Road!F6/100 -> 123032.58 | X6: =D6*Road!G6/100 -> 20898.184 | Y6: =E6*Road!I6/100 -> 4458.6047 | Z6: =G6*Rail!E6/100 -> -14005.717 | AA6: =H6*Rail!F6/100 -> 4132.3489 | AB6: =F6*IWW!D6/100 -> 20278.503 | AD6: =(C6+D6)*Road!J6/100 -> 85973.983 | AE6: =E6*Road!L6/100 -> 9741.2453 | AF6: =G6*Rail!G6/100 -> -6542.144 | AG6: =H6*Rail!I6/100 -> 1187.4566 | AH6: =(C6+D6)*Road!K6/100 -> 98727.54 | AI6: =E6*Road!M6/100 -> 4350.4688 | AJ6: =G6*Rail!H6/100 -> -3685.715 | AK6: =H6*Rail!J6/100 -> 3134.8853
A7: =A49 -> 10 | B7: =IF(B49='S00 Impact'!B6,B49,0) -> BG | C7: =-(C49-'S00 Impact'!C6) -> -1.8039222e+09 | D7: =-(D49-'S00 Impact'!D6) -> -4.1058798e+08 | E7: =-(E49-'S00 Impact'!E6) -> -11078412 | F7: =-(F49-'S00 Impact'!F6) -> 67569.391 | G7: =-(G49-'S00 Impact'!G6) -> -1.2400438e+09 | H7: =-(H49-'S00 Impact'!H6) -> 1.6108526e+09 | N7: =A7 -> 10 | O7: =B7 -> BG | P7: =C7*Road!D7/100 -> -1443137.8 | Q7: =D7*Road!E7/100 -> -932034.72 | R7: =E7*Road!H7/100 -> -192210.45 | S7: =G7*Rail!C7/100 -> -582820.61 | T7: =H7*Rail!D7/100 -> 434930.19 | U7: =F7*IWW!C7/100 -> 317.57614 | W7: =C7*Road!F7/100 -> -17299614 | X7: =D7*Road!G7/100 -> -3925221.1 | Y7: =E7*Road!I7/100 -> -493321.68 | Z7: =G7*Rail!E7/100 -> -1884866.6 | AA7: =H7*Rail!F7/100 -> 1401441.7 | AB7: =F7*IWW!D7/100 -> 183.78874 | AD7: =(C7+D7)*Road!J7/100 -> -6975707 | AE7: =E7*Road!L7/100 -> -111227.25 | AF7: =G7*Rail!G7/100 -> -1054037.3 | AG7: =H7*Rail!I7/100 -> 434930.19 | AH7: =(C7+D7)*Road!K7/100 -> -5757726.5 | AI7: =E7*Road!M7/100 -> -249818.19 | AJ7: =G7*Rail!H7/100 -> -2666094.3 | AK7: =H7*Rail!J7/100 -> 483255.77
A8: =A50 -> 10 | B8: =IF(B50='S00 Impact'!B7,B50,0) -> BY | C8: =-(C50-'S00 Impact'!C7) -> 39995418 | D8: =-(D50-'S00 Impact'!D7) -> 8085517.6 | E8: =-(E50-'S00 Impact'!E7) -> 19546749 | F8: =-(F50-'S00 Impact'!F7) -> 0 | G8: =-(G50-'S00 Impact'!G7) -> 39937318 | H8: =-(H50-'S00 Impact'!H7) -> -60981352 | N8: =A8 -> 10 | O8: =B8 -> BY | P8: =C8*Road!D8/100 -> 40395.372 | Q8: =D8*Road!E8/100 -> 23043.725 | R8: =E8*Road!H8/100 -> 425532.74 | S8: =G8*Rail!C8/100 -> 29553.615 | T8: =H8*Rail!D8/100 -> -26831.795 | U8: =F8*IWW!C8/100 -> 0 | W8: =C8*Road!F8/100 -> 383556.06 | X8: =D8*Road!G8/100 -> 77297.549 | Y8: =E8*Road!I8/100 -> 870416.75 | Z8: =G8*Rail!E8/100 -> 60704.723 | AA8: =H8*Rail!F8/100 -> -53053.777 | AB8: =F8*IWW!D8/100 -> 0 | AD8: =(C8+D8)*Road!J8/100 -> 190400.5 | AE8: =E8*Road!L8/100 -> 246093.58 | AF8: =G8*Rail!G8/100 -> 28355.496 | AG8: =H8*Rail!I8/100 -> -16464.965 | AH8: =(C8+D8)*Road!K8/100 -> 157224.66 | AI8: =E8*Road!M8/100 -> 552977.54 | AJ8: =G8*Rail!H8/100 -> 12380.569 | AK8: =H8*Rail!J8/100 -> -20733.66
A9: =A51 -> 10 | B9: =IF(B51='S00 Impact'!B8,B51,0) -> CH | C9: =-(C51-'S00 Impact'!C8) -> -9321981.4 | D9: =-(D51-'S00 Impact'!D8) -> -5163097.8 | E9: =-(E51-'S00 Impact'!E8) -> 4601611.6 | F9: =-(F51-'S00 Impact'!F8) -> 343937.98 | G9: =-(G51-'S00 Impact'!G8) -> 5964163.8 | H9: =-(H51-'S00 Impact'!H8) -> 31123177 | N9: =A9 -> 10 | O9: =B9 -> CH | P9: =C9*Road!D9/100 -> -28804.922 | Q9: =D9*Road!E9/100 -> -45073.843 | R9: =E9*Road!H9/100 -> 306559.36 | S9: =G9*Rail!C9/100 -> 2385.6655 | T9: =H9*Rail!D9/100 -> 7158.3308 | U9: =F9*IWW!C9/100 -> 6452.2765 | W9: =C9*Road!F9/100 -> -89397.802 | X9: =D9*Road!G9/100 -> -49359.215 | Y9: =E9*Road!I9/100 -> 204909.76 | Z9: =G9*Rail!E9/100 -> 9065.529 | AA9: =H9*Rail!F9/100 -> 27077.164 | AB9: =F9*IWW!D9/100 -> 935.5113 | AD9: =(C9+D9)*Road!J9/100 -> -175414.31 | AE9: =E9*Road!L9/100 -> 177392.13 | AF9: =G9*Rail!G9/100 -> 8230.5461 | AG9: =H9*Rail!I9/100 -> 4357.2448 | AH9: =(C9+D9)*Road!K9/100 -> -144850.79 | AI9: =E9*Road!M9/100 -> 398407.53 | AJ9: =G9*Rail!H9/100 -> 13121.16 | AK9: =H9*Rail!J9/100 -> 18362.675
A10: =A52 -> 10 | B10: =IF(B52='S00 Impact'!B9,B52,0) -> CZ | C10: =-(C52-'S00 Impact'!C9) -> -3.6809602e+08 | D10: =-(D52-'S00 Impact'!D9) -> -78279129 | E10: =-(E52-'S00 Impact'!E9) -> -6202531.1 | F10: =-(F52-'S00 Impact'!F9) -> -6167.3151 | G10: =-(G52-'S00 Impact'!G9) -> 18940931 | H10: =-(H52-'S00 Impact'!H9) -> -59988953 | N10: =A10 -> 10 | O10: =B10 -> CZ | P10: =C10*Road!D10/100 -> -533739.23 | Q10: =D10*Road!E10/100 -> -324075.59 | R10: =E10*Road!H10/100 -> -196124.03 | S10: =G10*Rail!C10/100 -> 15342.154 | T10: =H10*Rail!D10/100 -> -25795.25 | U10: =F10*IWW!C10/100 -> -115.69883 | W10: =C10*Road!F10/100 -> -3533721.8 | X10: =D10*Road!G10/100 -> -747565.68 | Y10: =E10*Road!I10/100 -> -276198.71 | Z10: =G10*Rail!E10/100 -> 28790.215 | AA10: =H10*Rail!F10/100 -> -52190.389 | AB10: =F10*IWW!D10/100 -> -16.775097 | AD10: =(C10+D10)*Road!J10/100 -> -990952.84 | AE10: =E10*Road!L10/100 -> -120763.28 | AF10: =G10*Rail!G10/100 -> 10417.512 | AG10: =H10*Rail!I10/100 -> -16796.907 | AH10: =(C10+D10)*Road!K10/100 -> -2205093.2 | AI10: =E10*Road!M10/100 -> -300264.53 | AJ10: =G10*Rail!H10/100 -> 18940.931 | AK10: =H10*Rail!J10/100 -> -76785.86
A11: =A53 -> 10 | B11: =IF(B53='S00 Impact'!B10,B53,0) -> DE | C11: =-(C53-'S00 Impact'!C10) -> -4.4749235e+08 | D11: =-(D53-'S00 Impact'!D10) -> -1.0326924e+08 | E11: =-(E53-'S00 Impact'!E10) -> -38669.076 | F11: =-(F53-'S00 Impact'!F10) -> -1550662.7 | G11: =-(G53-'S00 Impact'!G10) -> -5.7245521e+08 | H11: =-(H53-'S00 Impact'!H10) -> -34047.561 | N11: =A11 -> 10 | O11: =B11 -> DE | P11: =C11*Road!D11/100 -> -662288.67 | Q11: =D11*Road!E11/100 -> -632007.74 | R11: =E11*Road!H11/100 -> -1904.0653 | S11: =G11*Rail!C11/100 -> -200359.32 | T11: =H11*Rail!D11/100 -> -6.8095122 | U11: =F11*IWW!C11/100 -> -37665.597 | W11: =C11*Road!F11/100 -> -4295926.5 | X11: =D11*Road!G11/100 -> -986221.23 | Y11: =E11*Road!I11/100 -> -1721.9339 | Z11: =G11*Rail!E11/100 -> -870131.92 | AA11: =H11*Rail!F11/100 -> -29.621378 | AB11: =F11*IWW!D11/100 -> -4217.8026 | AD11: =(C11+D11)*Road!J11/100 -> -2092894 | AE11: =E11*Road!L11/100 -> -1489.9195 | AF11: =G11*Rail!G11/100 -> -486586.93 | AG11: =H11*Rail!I11/100 -> -9.1928415 | AH11: =(C11+D11)*Road!K11/100 -> -3216447.7 | AI11: =E11*Road!M11/100 -> -1491.0796 | AJ11: =G11*Rail!H11/100 -> -818610.95 | AK11: =H11*Rail!J11/100 -> -12.938073
A12: =A54 -> 10 | B12: =IF(B54='S00 Impact'!B11,B54,0) -> DK | C12: =-(C54-'S00 Impact'!C11) -> -1.0643979e+08 | D12: =-(D54-'S00 Impact'!D11) -> -25434360 | E12: =-(E54-'S00 Impact'!E11) -> 8665957 | F12: =-(F54-'S00 Impact'!F11) -> 0 | G12: =-(G54-'S00 Impact'!G11) -> 18040301 | H12: =-(H54-'S00 Impact'!H11) -> -21216.629 | N12: =A12 -> 10 | O12: =B12 -> DK | P12: =C12*Road!D12/100 -> -146886.91 | Q12: =D12*Road!E12/100 -> -92835.415 | R12: =E12*Road!H12/100 -> 239353.73 | S12: =G12*Rail!C12/100 -> 8298.5384 | T12: =H12*Rail!D12/100 -> -6.5771549 | U12: =F12*IWW!C12/100 -> 0 | W12: =C12*Road!F12/100 -> -1021822 | X12: =D12*Road!G12/100 -> -242898.14 | Y12: =E12*Road!I12/100 -> 385895.07 | Z12: =G12*Rail!E12/100 -> 27421.257 | AA12: =H12*Rail!F12/100 -> -18.458467 | AB12: =F12*IWW!D12/100 -> 0 | AD12: =(C12+D12)*Road!J12/100 -> -514309.18 | AE12: =E12*Road!L12/100 -> 310501.24 | AF12: =G12*Rail!G12/100 -> 10282.971 | AG12: =H12*Rail!I12/100 -> -6.5771549 | AH12: =(C12+D12)*Road!K12/100 -> -1131480.2 | AI12: =E12*Road!M12/100 -> 490753.15 | AJ12: =G12*Rail!H12/100 -> 9561.3595 | AK12: =H12*Rail!J12/100 -> -27.157285
A13: =A55 -> 10 | B13: =IF(B55='S00 Impact'!B12,B55,0) -> EE | C13: =-(C55-'S00 Impact'!C12) -> -6252838.3 | D13: =-(D55-'S00 Impact'!D12) -> -151811.41 | E13: =-(E55-'S00 Impact'!E12) -> 6535735.8 | F13: =-(F55-'S00 Impact'!F12) -> 0 | G13: =-(G55-'S00 Impact'!G12) -> -1480216 | H13: =-(H55-'S00 Impact'!H12) -> -26942454 | N13: =A13 -> 10 | O13: =B13 -> EE | P13: =C13*Road!D13/100 -> -12943.375 | Q13: =D13*Road!E13/100 -> -894.16923 | R13: =E13*Road!H13/100 -> 294108.11 | S13: =G13*Rail!C13/100 -> -4707.0868 | T13: =H13*Rail!D13/100 -> -49304.69 | U13: =F13*IWW!C13/100 -> 0 | W13: =C13*Road!F13/100 -> -60027.248 | X13: =D13*Road!G13/100 -> -1449.799 | Y13: =E13*Road!I13/100 -> 291036.31 | Z13: =G13*Rail!E13/100 -> -2249.9283 | AA13: =H13*Rail!F13/100 -> -23439.935 | AB13: =F13*IWW!D13/100 -> 0 | AD13: =(C13+D13)*Road!J13/100 -> -14410.462 | AE13: =E13*Road!L13/100 -> 181105.24 | AF13: =G13*Rail!G13/100 -> -1050.9533 | AG13: =H13*Rail!I13/100 -> -9160.4342 | AH13: =(C13+D13)*Road!K13/100 -> -45024.688 | AI13: =E13*Road!M13/100 -> 450181.48 | AJ13: =G13*Rail!H13/100 -> -562.48207 | AK13: =H13*Rail!J13/100 -> -53346.058
A14: =A56 -> 10 | B14: =IF(B56='S00 Impact'!B13,B56,0) -> ES | C14: =-(C56-'S00 Impact'!C13) -> -1.1619115e+08 | D14: =-(D56-'S00 Impact'!D13) -> -42747907 | E14: =-(E56-'S00 Impact'!E13) -> 738890.52 | F14: =-(F56-'S00 Impact'!F13) -> 0 | G14: =-(G56-'S00 Impact'!G13) -> 1.1502058e+08 | H14: =-(H56-'S00 Impact'!H13) -> 5801362.6 | N14: =A14 -> 10 | O14: =B14 -> ES | P14: =C14*Road!D14/100 -> -197524.95 | Q14: =D14*Road!E14/100 -> -145770.36 | R14: =E14*Road!H14/100 -> 17977.206 | S14: =G14*Rail!C14/100 -> 37956.792 | T14: =H14*Rail!D14/100 -> 1102.2589 | U14: =F14*IWW!C14/100 -> 0 | W14: =C14*Road!F14/100 -> -1115435 | X14: =D14*Road!G14/100 -> -408242.51 | Y14: =E14*Road!I14/100 -> 32902.795 | Z14: =G14*Rail!E14/100 -> 174831.28 | AA14: =H14*Rail!F14/100 -> 5047.1855 | AB14: =F14*IWW!D14/100 -> 0 | AD14: =(C14+D14)*Road!J14/100 -> -716815.12 | AE14: =E14*Road!L14/100 -> 3664.897 | AF14: =G14*Rail!G14/100 -> 73613.171 | AG14: =H14*Rail!I14/100 -> 1566.3679 | AH14: =(C14+D14)*Road!K14/100 -> -912310.16 | AI14: =E14*Road!M14/100 -> 27996.562 | AJ14: =G14*Rail!H14/100 -> 187483.55 | AK14: =H14*Rail!J14/100 -> 1682.3952
A15: =A57 -> 10 | B15: =IF(B57='S00 Impact'!B14,B57,0) -> FI | C15: =-(C57-'S00 Impact'!C14) -> 16277406 | D15: =-(D57-'S00 Impact'!D14) -> 4263410 | E15: =-(E57-'S00 Impact'!E14) -> 825545.88 | F15: =-(F57-'S00 Impact'!F14) -> 0 | G15: =-(G57-'S00 Impact'!G14) -> -1357643.5 | H15: =-(H57-'S00 Impact'!H14) -> -11146628 | N15: =A15 -> 10 | O15: =B15 -> FI | P15: =C15*Road!D15/100 -> 31252.62 | Q15: =D15*Road!E15/100 -> 23278.218 | R15: =E15*Road!H15/100 -> 34417.008 | S15: =G15*Rail!C15/100 -> -502.3281 | T15: =H15*Rail!D15/100 -> -3901.3198 | U15: =F15*IWW!C15/100 -> 0 | W15: =C15*Road!F15/100 -> 156263.1 | X15: =D15*Road!G15/100 -> 40715.565 | Y15: =E15*Road!I15/100 -> 36761.558 | Z15: =G15*Rail!E15/100 -> -2063.6181 | AA15: =H15*Rail!F15/100 -> -9697.5664 | AB15: =F15*IWW!D15/100 -> 0 | AD15: =(C15+D15)*Road!J15/100 -> 92844.49 | AE15: =E15*Road!L15/100 -> 21191.763 | AF15: =G15*Rail!G15/100 -> -1262.6085 | AG15: =H15*Rail!I15/100 -> -4793.0501 | AH15: =(C15+D15)*Road!K15/100 -> 133720.71 | AI15: =E15*Road!M15/100 -> 52686.338 | AJ15: =G15*Rail!H15/100 -> -1506.9843 | AK15: =H15*Rail!J15/100 -> -14825.015
... A41: =A83 -> 10 | B41: =IF(B83='S00 Impact'!B40,B83,0) -> YU | C41: =-(C83-'S00 Impact'!C40) -> 2.1737542e+09 | D41: =-(D83-'S00 Impact'!D40) -> 4.8155212e+08 | E41: =-(E83-'S00 Impact'!E40) -> 6842417.5 | F41: =-(F83-'S00 Impact'!F40) -> -502038.3 | G41: =-(G83-'S00 Impact'!G40) -> 4.1415275e+09 | H41: =-(H83-'S00 Impact'!H40) -> 8.1087991e+08 | N41: =A41 -> 10 | O41: =B41 -> YU | P41: =C41*Road!D41/100 -> 1956378.8 | Q41: =D41*Road!E41/100 -> 1232773.4 | R41: =E41*Road!H41/100 -> 133427.14 | S41: =G41*Rail!C41/100 -> 1739441.5 | T41: =H41*Rail!D41/100 -> 194611.18 | U41: =F41*IWW!C41/100 -> -6385.9272 | W41: =C41*Road!F41/100 -> 20846303 | X41: =D41*Road!G41/100 -> 4603638.3 | Y41: =E41*Road!I41/100 -> 304692.85 | Z41: =G41*Rail!E41/100 -> 6295121.8 | AA41: =H41*Rail!F41/100 -> 705465.53 | AB41: =F41*IWW!D41/100 -> -1365.5442 | AD41: =(C41+D41)*Road!J41/100 -> 9426337.4 | AE41: =E41*Road!L41/100 -> 77182.469 | AF41: =G41*Rail!G41/100 -> 2940484.5 | AG41: =H41*Rail!I41/100 -> 218937.58 | AH41: =(C41+D41)*Road!K41/100 -> 7780047.5 | AI41: =E41*Road!M41/100 -> 173386.86 | AJ41: =G41*Rail!H41/100 -> 1573780.4 | AK41: =H41*Rail!J41/100 -> 397331.16
N42: =N41 -> 10 | O42: Total | P42: =SUM(P3:P41) -> -7384879.5 | Q42: =SUM(Q3:Q41) -> -5478187.8 | R42: =SUM(R3:R41) -> 6928189.3 | S42: =SUM(S3:S41) -> 2384968.7 | T42: =SUM(T3:T41) -> -66137.378 | U42: =SUM(U3:U41) -> 185827.93 | V42: =L3*Air!C3/100 -> 9896469.3 | W42: =SUM(W3:W41) -> -47451967 | X42: =SUM(X3:X41) -> -11419531 | Y42: =SUM(Y3:Y41) -> 15089197 | Z42: =SUM(Z3:Z41) -> -2903285.7 | AA42: =SUM(AA3:AA41) -> -385515.69 | AB42: =SUM(AB3:AB41) -> 26453.15 | AC42: =L3*Air!D3/100 -> 7177817.1 | AD42: =SUM(AD3:AD41) -> -22369885 | AE42: =SUM(AE3:AE41) -> 3432348 | AF42: =SUM(AF3:AF41) -> -1726698.9 | AG42: =SUM(AG3:AG41) -> -103615.17 | AH42: =SUM(AH3:AH41) -> -24076537 | AI42: =SUM(AI3:AI41) -> 11212804 | AJ42: =SUM(AJ3:AJ41) -> -5162900.1 | AK42: =SUM(AK3:AK41) -> -2433573.6 | AL42: =SUM(P42:AK42) -> -74628639
V43: =SUM(P42:V42) -> 6466250.5 | AC43: =SUM(W42:AC42) -> -39866832 | AG43: =SUM(AD42:AG42) -> -20767851 | AK43: =SUM(AH42:AK42) -> -20460206
A44: scenario | B44: CountryCode | C44: vkm_petrol_Carpassenger | D44: vkm_diesel_Carpassenger | E44: vkm_hgv_Freight | F44: Total_IWW_TonKM | G44: PersonKM_RailPassenger | H44: TonKM_RailFreight | J44: _TYPE_ | K44: _FREQ_ | L44: personkm_Air
A45: 10 | B45: AL | C45: 2.1888114e+09 | D45: 5.4161304e+08 | E45: 7.7757649e+08 | G45: 1.2740437e+08 | H45: 5.9726357e+08 | J45: 0 | K45: 3153 | L45: 8.3785536e+11
A46: 10 | B46: AT | C46: 4.3142986e+10 | D46: 2.7062851e+10 | E46: 6.9156776e+09 | F46: 7.1090553e+09 | G46: 1.6264196e+10 | H46: 2.480397e+10
A47: 10 | B47: BA | C47: 4.9429243e+09 | D47: 1.2120968e+09 | E47: 8.7251077e+08 | F47: 7.3957669e+08 | G47: 5.9825823e+08 | H47: 1.2101454e+09
A48: 10 | B48: BE | C48: 4.2884992e+10 | D48: 3.2551601e+10 | E48: 8.4077116e+09 | F48: 9.5812004e+09 | G48: 1.4162124e+10 | H48: 9.8102873e+09
A49: 10 | B49: BG | C49: 2.9775341e+10 | D49: 7.2457053e+09 | E49: 3.8517766e+09 | F49: 2.1005669e+09 | G49: 1.8250004e+10 | H49: 2.139897e+10
A50: 10 | B50: BY | C50: 1.9193013e+10 | D50: 4.6283042e+09 | E50: 1.0415673e+10 | G50: 7.671675e+09 | H50: 2.7012447e+10
A51: 10 | B51: CH | C51: 3.9955859e+10 | D51: 5.7181002e+09 | E51: 3.638905e+09 | F51: 38597464 | G51: 1.1673007e+10 | H51: 1.1526181e+10
A52: 10 | B52: CZ | C52: 3.2098599e+10 | D52: 6.968781e+09 | E52: 8.5538905e+09 | F52: 45308333 | G52: 9.3418324e+09 | H52: 3.5427281e+10
A53: 10 | B53: DE | C53: 3.804571e+11 | D53: 8.877518e+10 | E53: 4.6527718e+10 | F53: 7.5686299e+10 | G53: 1.1547213e+11 | H53: 1.1011041e+11
A54: 10 | B54: DK | C54: 3.7351207e+10 | D54: 3.891281e+09 | E54: 7.2340646e+09 | G54: 6.3667081e+09 | H54: 3.3950317e+09
A55: 10 | B55: EE | C55: 3.3629018e+09 | D55: 6.0979473e+08 | E55: 1.8134328e+09 | G55: 2.9172185e+08 | H55: 3.1022519e+10
A56: 10 | B56: ES | C56: 1.7622195e+11 | D56: 9.4507834e+10 | E56: 4.8188394e+10 | G56: 2.9395184e+10 | H56: 2.4310556e+10
A57: 10 | B57: FI | C57: 2.9644208e+10 | D57: 4.3253409e+09 | E57: 5.6531433e+09 | G57: 7.6564498e+09 | H57: 2.2116287e+10
A58: 10 | B58: FR | C58: 2.4560397e+11 | D58: 1.6783922e+11 | E58: 4.4050754e+10 | F58: 1.2012701e+10 | G58: 9.5516405e+10 | H58: 5.5786633e+10
A59: 10 | B59: GR | C59: 2.7429018e+10 | D59: 6.790787e+09 | E59: 6.2561022e+09 | G59: 3.0235197e+09 | H59: 1.4138327e+09
A60: 10 | B60: HR | C60: 2.2176193e+10 | D60: 5.5141618e+09 | E60: 2.6611783e+09 | F60: 3.1227054e+08 | G60: 8.4646461e+09 | H60: 8.0282534e+09
A61: 10 | B61: HU | C61: 3.0629196e+10 | D61: 6.3156286e+09 | E61: 5.4094575e+09 | F61: 1.118554e+10 | G61: 1.6093275e+10 | H61: 2.3374475e+10
A62: 10 | B62: IE | C62: 2.7574845e+10 | D62: 4.7715534e+09 | E62: 4.8690082e+09 | G62: 1.9366195e+09 | H62: 6.5522891e+08
A63: 10 | B63: IT | C63: 2.1165353e+11 | D63: 5.5789359e+10 | E63: 3.6751618e+10 | G63: 5.0345754e+10 | H63: 3.579201e+10
A64: 10 | B64: LI | C64: 80624315 | D64: 23897855 | E64: 17694815 | G64: 12721579 | H64: 28926562
A65: 10 | B65: LT | C65: 8.54473e+09 | D65: 2.0373578e+09 | E65: 4.6397713e+09 | F65: 1945882.9 | G65: 1.3282965e+10 | H65: 3.6753826e+10
...

Sheet S18 Impact
A1: Difference from Baseline | O1: Type | P1: Air Pollution | Q1: Air Pollution | R1: Air Pollution | S1: Air Pollution | T1: Air Pollution | U1: Air Pollution | V1: Air Pollution | W1: Global Warming | X1: Global Warming | Y1: Global Warming | Z1: Global Warming | AA1: Global Warming | AB1: Global Warming | AC1: Global Warming | AD1: Accidents | AE1: Accidents | AF1: Accidents | AG1: Accidents | AH1: Noise | AI1: Noise | AJ1: Noise | AK1: Noise
A2: Scenario | B2: CountryCode | C2: vkm_petrol_Carpassenger | D2: vkm_diesel_Carpassenger | E2: vkm_hgv_Freight | F2: Total_IWW_TonKM | G2: PersonKM_RailPassenger | H2: TonKM_RailFreight | J2: _TYPE_ | K2: _FREQ_ | L2: personkm_Air | N2: Scenario | O2: CountryCode | P2: Car Petrol (€) | Q2: Car Diesel (€) | R2: HGV Diesel (€) | S2: Train Person (€) | T2: Train Freight (€) | U2: IWW (€) | V2: Air (€) | W2: Car Petrol (€) | X2: Car Diesel (€) | Y2: HGV Diesel (€) | Z2: Train Person (€) | AA2: Train Freight (€) | AB2: IWW (€) | AC2: Air (€) | AD2: Car (€) | AE2: HGV (€) | AF2: Train Person (€) | AG2: Train Freight (€) | AH2: Car (€) | AI2: HGV (€) | AJ2: Train Person (€) | AK2: Train Freight (€)
