Workbook

Sheet ELECTRE - Alif
C2: Weight | D2: 5 | E2: 8 | F2: 7 | G2: 3 | H2: 9 | I2: 2
B3: Scenario no. | C3: Scenarios | D3: Environmental Impact | E3: Cross-Border Connectivity & Network Integration | F3: Cost (CAPEX + O&M) | G3: Complexity/ Feasibility | H3: Socio Economic Benefits | I3: Safety & Resilience
B4: 1 | C4: Railway axis Berlin-Verona/Milano-Bologna-Napoli-Messina-Palermo
B5: 3 | C5: High-speed railway axis of southwest Europe
B6: 9 | C6: Railway axis Cork–Dublin–Belfast–Stranraer
B7: 10 | C7: Malpensa airport
B8: 11 | C8: Øresund bridge
B9: 12 | C9: Nordic Triangle railway/road axis
B10: 13 | C10: Road axis United Kingdom/Ireland/Benelux
B11: 16 | C11: Freight railway axis Sines/Algeciras-Madrid-Paris
B12: 18 | C12: Waterway axis Rhine/Meuse-Main-Danube
B13: 20 | C13: Railway axis Fehmarn belt

Sheet ELECTRE - Levente
C2: Weight | D2: 2 | E2: 7 | F2: 5 | G2: 3 | H2: 10 | I2: 1 | K2: weights are just my opinion
B3: Scenario no. | C3: Scenarios | D3: Environmental Impact | E3: Cross-Border Connectivity & Network Integration | F3: Cost (CAPEX + O&M) | G3: Complexity/ Feasibility | H3: Socio Economic Benefits | I3: Safety & Resilience
B4: 1 | C4: Railway axis Berlin-Verona/Milano-Bologna-Napoli-Messina-Palermo | D4: 4 | E4: 4 | F4: 1 | G4: 1 | H4: 5
B5: 3 | C5: High-speed railway axis of southwest Europe | D5: 5 | E5: 2 | F5: 2 | G5: 3 | H5: 3
B6: 9 | C6: Railway axis Cork–Dublin–Belfast–Stranraer | D6: 3 | E6: 5 | F6: 1 | G6: 1 | H6: 4
B7: 10 | C7: Malpensa airport | D7: 3 | E7: 3 | F7: 1 | G7: 2 | H7: 4
B8: 11 | C8: Øresund bridge | D8: 4 | E8: 1 | F8: 2 | G8: 3 | H8: 3
B9: 12 | C9: Nordic Triangle railway/road axis | D9: 3 | E9: 1 | F9: 2 | G9: 3 | H9: 2
B10: 13 | C10: Road axis United Kingdom/Ireland/Benelux | D10: 4 | E10: 1 | F10: 4 | G10: 4 | H10: 1
B11: 16 | C11: Freight railway axis Sines/Algeciras-Madrid-Paris | D11: 2 | E11: 1 | F11: 1 | G11: 2 | H11: 2
B12: 18 | C12: Waterway axis Rhine/Meuse-Main-Danube | D12: 4 | E12: 3 | F12: 2 | G12: 1 | H12: 5
B13: 20 | C13: Railway axis Fehmarn belt | D13: 3 | E13: 1 | F13: 3 | G13: 2 | H13: 5
D16: overall very low, no new areas for high impact, improvements break even at latest 15 years (low weight) | E16: no. of countries. but some of the biggest benefits would come from no. 20 for many countries | F16: cost/benefit would be better, this one disincentivize larger projects. based on ranges in the key. wight for cost. weight for cost/benefit is under socio-economic | G16: mostly complexity, all are feasible (on track to be operational latest 2050) | H16: for now used as cost/benefit
F17: Projected cost/benefit
B18: 1 | F18: 5
B19: 3 | F19: 3
B20: 9 | F20: 4
B21: 10 | F21: 4
B22: 11 | F22: 3
B23: 12 | F23: 2
B24: 13 | F24: 1
B25: 16 | F25: 2
B26: 18 | F26: 5
B27: 20 | F27: 5

Sheet ELECTRE - Joao
C2: Weight
B3: Scenario no. | C3: Scenarios | D3: Environmental Impact | E3: Cross-Border Connectivity & Network Integration | F3: Cost (CAPEX + O&M) | G3: Complexity/ Feasibility | H3: Socio Economic Benefits | I3: Safety & Resilience
B4: 1 | C4: Railway axis Berlin-Verona/Milano-Bologna-Napoli-Messina-Palermo
B5: 3 | C5: High-speed railway axis of southwest Europe
B6: 9 | C6: Railway axis Cork–Dublin–Belfast–Stranraer
B7: 10 | C7: Malpensa airport
B8: 11 | C8: Øresund bridge
B9: 12 | C9: Nordic Triangle railway/road axis
B10: 13 | C10: Road axis United Kingdom/Ireland/Benelux
B11: 16 | C11: Freight railway axis Sines/Algeciras-Madrid-Paris
B12: 18 | C12: Waterway axis Rhine/Meuse-Main-Danube
B13: 20 | C13: Railway axis Fehmarn belt

Sheet ELECTRE - Dante
C2: Weight | D2: 8 | E2: 10 | F2: 7 | G2: 5 | H2: 8 | I2: 4
B3: Scenario no. | C3: Scenarios | D3: Environmental Impact | E3: Cross-Border Connectivity & Network Integration | F3: Cost (CAPEX + O&M) | G3: Complexity/ Feasibility | H3: Socio Economic Benefits | I3: Safety & Resilience
B4: 1 | C4: Railway axis Berlin-Verona/Milano-Bologna-Napoli-Messina-Palermo | D4: 4 | E4: 5 | F4: 2 | G4: 2 | H4: 5 | I4: 4
B5: 3 | C5: High-speed railway axis of southwest Europe | D5: 3 | E5: 4 | F5: 4 | G5: 3 | H5: 4 | I5: 3
B6: 9 | C6: Railway axis Cork–Dublin–Belfast–Stranraer | D6: 3 | E6: 5 | F6: 1 | G6: 3 | H6: 4 | I6: 3
B7: 10 | C7: Malpensa airport | D7: 3 | E7: 4 | F7: 3 | G7: 3 | H7: 4 | I7: 3
B8: 11 | C8: Øresund bridge | D8: 3 | E8: 3 | F8: 4 | G8: 4 | H8: 3 | I8: 3
B9: 12 | C9: Nordic Triangle railway/road axis | D9: 3 | E9: 4 | F9: 5 | G9: 3 | H9: 4 | I9: 4
B10: 13 | C10: Road axis United Kingdom/Ireland/Benelux | D10: 4 | E10: 2 | F10: 5 | G10: 5 | H10: 3 | I10: 3
B11: 16 | C11: Freight railway axis Sines/Algeciras-Madrid-Paris | D11: 4 | E11: 2 | F11: 4 | G11: 2 | H11: 4 | I11: 4
B12: 18 | C12: Waterway axis Rhine/Meuse-Main-Danube | D12: 4 | E12: 5 | F12: 3 | G12: 3 | H12: 5 | I12: 4
B13: 20 | C13: Railway axis Fehmarn belt | D13: 3 | E13: 3 | F13: 5 | G13: 4 | H13: 4 | I13: 3

Sheet ELECTRE - Average
E2: Weight | F2: 4 | G2: 8 | H2: 6 | I2: 4 | J2: 9 | K2: 2
B3: Average | D3: Scenario no. | F3: Environmental Impact | G3: Cross-Border Connectivity & Network Integration | H3: Cost (CAPEX + O&M) | I3: Complexity/ Feasibility | J3: Socio Economic Benefits | K3: Safety & Resilience
D4: 1 | F4: =AVERAGE('ELECTRE - Alif'!D4,'ELECTRE - Levente'!D4,'ELECTRE - Joao'!D4,'ELECTRE - Dante'!D4) -> 4 | G4: 4 | H4: 2 | I4: 1 | J4: =AVERAGE('ELECTRE - Alif'!H4,'ELECTRE - Levente'!H4,'ELECTRE - Joao'!H4,'ELECTRE - Dante'!H4) -> 5 | K4: =AVERAGE('ELECTRE - Alif'!I4,'ELECTRE - Levente'!I4,'ELECTRE - Joao'!I4,'ELECTRE - Dante'!I4) -> 4
D5: 3 | F5: =AVERAGE('ELECTRE - Alif'!D5,'ELECTRE - Levente'!D5,'ELECTRE - Joao'!D5,'ELECTRE - Dante'!D5) -> 4 | G5: =AVERAGE('ELECTRE - Alif'!E5,'ELECTRE - Levente'!E5,'ELECTRE - Joao'!E5,'ELECTRE - Dante'!E5) -> 3 | H5: 4 | I5: =AVERAGE('ELECTRE - Alif'!G5,'ELECTRE - Levente'!G5,'ELECTRE - Joao'!G5,'ELECTRE - Dante'!G5) -> 3 | J5: 3 | K5: =AVERAGE('ELECTRE - Alif'!I5,'ELECTRE - Levente'!I5,'ELECTRE - Joao'!I5,'ELECTRE - Dante'!I5) -> 3
D6: 9 | F6: =AVERAGE('ELECTRE - Alif'!D6,'ELECTRE - Levente'!D6,'ELECTRE - Joao'!D6,'ELECTRE - Dante'!D6) -> 3 | G6: =AVERAGE('ELECTRE - Alif'!E6,'ELECTRE - Levente'!E6,'ELECTRE - Joao'!E6,'ELECTRE - Dante'!E6) -> 5 | H6: 1 | I6: =AVERAGE('ELECTRE - Alif'!G6,'ELECTRE - Levente'!G6,'ELECTRE - Joao'!G6,'ELECTRE - Dante'!G6) -> 2 | J6: =AVERAGE('ELECTRE - Alif'!H6,'ELECTRE - Levente'!H6,'ELECTRE - Joao'!H6,'ELECTRE - Dante'!H6) -> 4 | K6: =AVERAGE('ELECTRE - Alif'!I6,'ELECTRE - Levente'!I6,'ELECTRE - Joao'!I6,'ELECTRE - Dante'!I6) -> 3
D7: 10 | F7: =AVERAGE('ELECTRE - Alif'!D7,'ELECTRE - Levente'!D7,'ELECTRE - Joao'!D7,'ELECTRE - Dante'!D7) -> 3 | G7: 4 | H7: 3 | I7: 3 | J7: =AVERAGE('ELECTRE - Alif'!H7,'ELECTRE - Levente'!H7,'ELECTRE - Joao'!H7,'ELECTRE - Dante'!H7) -> 4 | K7: =AVERAGE('ELECTRE - Alif'!I7,'ELECTRE - Levente'!I7,'ELECTRE - Joao'!I7,'ELECTRE - Dante'!I7) -> 3
D8: 11 | F8: 3 | G8: 1 | H8: 4 | I8: 4 | J8: =AVERAGE('ELECTRE - Alif'!H8,'ELECTRE - Levente'!H8,'ELECTRE - Joao'!H8,'ELECTRE - Dante'!H8) -> 3 | K8: =AVERAGE('ELECTRE - Alif'!I8,'ELECTRE - Levente'!I8,'ELECTRE - Joao'!I8,'ELECTRE - Dante'!I8) -> 3
D9: 12 | F9: =AVERAGE('ELECTRE - Alif'!D9,'ELECTRE - Levente'!D9,'ELECTRE - Joao'!D9,'ELECTRE - Dante'!D9) -> 3 | G9: 2 | H9: 5 | I9: =AVERAGE('ELECTRE - Alif'!G9,'ELECTRE - Levente'!G9,'ELECTRE - Joao'!G9,'ELECTRE - Dante'!G9) -> 3 | J9: =AVERAGE('ELECTRE - Alif'!H9,'ELECTRE - Levente'!H9,'ELECTRE - Joao'!H9,'ELECTRE - Dante'!H9) -> 3 | K9: =AVERAGE('ELECTRE - Alif'!I9,'ELECTRE - Levente'!I9,'ELECTRE - Joao'!I9,'ELECTRE - Dante'!I9) -> 4
D10: 13 | F10: =AVERAGE('ELECTRE - Alif'!D10,'ELECTRE - Levente'!D10,'ELECTRE - Joao'!D10,'ELECTRE - Dante'!D10) -> 4 | G10: 1 | H10: 5 | I10: 5 | J10: =AVERAGE('ELECTRE - Alif'!H10,'ELECTRE - Levente'!H10,'ELECTRE - Joao'!H10,'ELECTRE - Dante'!H10) -> 2 | K10: =AVERAGE('ELECTRE - Alif'!I10,'ELECTRE - Levente'!I10,'ELECTRE - Joao'!I10,'ELECTRE - Dante'!I10) -> 3
D11: 16 | F11: =AVERAGE('ELECTRE - Alif'!D11,'ELECTRE - Levente'!D11,'ELECTRE - Joao'!D11,'ELECTRE - Dante'!D11) -> 3 | G11: 2 | H11: 4 | I11: =AVERAGE('ELECTRE - Alif'!G11,'ELECTRE - Levente'!G11,'ELECTRE - Joao'!G11,'ELECTRE - Dante'!G11) -> 2 | J11: =AVERAGE('ELECTRE - Alif'!H11,'ELECTRE - Levente'!H11,'ELECTRE - Joao'!H11,'ELECTRE - Dante'!H11) -> 3 | K11: =AVERAGE('ELECTRE - Alif'!I11,'ELECTRE - Levente'!I11,'ELECTRE - Joao'!I11,'ELECTRE - Dante'!I11) -> 4
D12: 18 | F12: =AVERAGE('ELECTRE - Alif'!D12,'ELECTRE - Levente'!D12,'ELECTRE - Joao'!D12,'ELECTRE - Dante'!D12) -> 4 | G12: 5 | H12: 3 | I12: =AVERAGE('ELECTRE - Alif'!G12,'ELECTRE - Levente'!G12,'ELECTRE - Joao'!G12,'ELECTRE - Dante'!G12) -> 2 | J12: =AVERAGE('ELECTRE - Alif'!H12,'ELECTRE - Levente'!H12,'ELECTRE - Joao'!H12,'ELECTRE - Dante'!H12) -> 5 | K12: =AVERAGE('ELECTRE - Alif'!I12,'ELECTRE - Levente'!I12,'ELECTRE - Joao'!I12,'ELECTRE - Dante'!I12) -> 4
D13: 20 | F13: =AVERAGE('ELECTRE - Alif'!D13,'ELECTRE - Levente'!D13,'ELECTRE - Joao'!D13,'ELECTRE - Dante'!D13) -> 3 | G13: 4 | H13: 5 | I13: =AVERAGE('ELECTRE - Alif'!G13,'ELECTRE - Levente'!G13,'ELECTRE - Joao'!G13,'ELECTRE - Dante'!G13) -> 3 | J13: 5 | K13: =AVERAGE('ELECTRE - Alif'!I13,'ELECTRE - Levente'!I13,'ELECTRE - Joao'!I13,'ELECTRE - Dante'!I13) -> 3
E15: Weight | F15: =MAX('ELECTRE - Alif'!D2,'ELECTRE - Levente'!D2,'ELECTRE - Joao'!D2,'ELECTRE - Dante'!D2) - MIN('ELECTRE - Alif'!D2,'ELECTRE - Levente'!D2,'ELECTRE - Joao'!D2,'ELECTRE - Dante'!D2) -> 6 | G15: =MAX('ELECTRE - Alif'!E2,'ELECTRE - Levente'!E2,'ELECTRE - Joao'!E2,'ELECTRE - Dante'!E2) - MIN('ELECTRE - Alif'!E2,'ELECTRE - Levente'!E2,'ELECTRE - Joao'!E2,'ELECTRE - Dante'!E2) -> 3 | H15: =MAX('ELECTRE - Alif'!F2,'ELECTRE - Levente'!F2,'ELECTRE - Joao'!F2,'ELECTRE - Dante'!F2) - MIN('ELECTRE - Alif'!F2,'ELECTRE - Levente'!F2,'ELECTRE - Joao'!F2,'ELECTRE - Dante'!F2) -> 2 | I15: =MAX('ELECTRE - Alif'!G2,'ELECTRE - Levente'!G2,'ELECTRE - Joao'!G2,'ELECTRE - Dante'!G2) - MIN('ELECTRE - Alif'!G2,'ELECTRE - Levente'!G2,'ELECTRE - Joao'!G2,'ELECTRE - Dante'!G2) -> 2 | J15: =MAX('ELECTRE - Alif'!H2,'ELECTRE - Levente'!H2,'ELECTRE - Joao'!H2,'ELECTRE - Dante'!H2) - MIN('ELECTRE - Alif'!H2,'ELECTRE - Levente'!H2,'ELECTRE - Joao'!H2,'ELECTRE - Dante'!H2) -> 2 | K15: =MAX('ELECTRE - Alif'!I2,'ELECTRE - Levente'!I2,'ELECTRE - Joao'!I2,'ELECTRE - Dante'!I2) - MIN('ELECTRE - Alif'!I2,'ELECTRE - Levente'!I2,'ELECTRE - Joao'!I2,'ELECTRE - Dante'!I2) -> 3
B16: Min/Max Difference | D16: Scenario no. | F16: Environmental Impact | G16: Cross-Border Connectivity & Network Integration | H16: Cost (CAPEX + O&M) | I16: Complexity/ Feasibility | J16: Socio Economic Benefits | K16: Safety & Resilience
D17: 1 | F17: =MAX('ELECTRE - Alif'!D4,'ELECTRE - Levente'!D4,'ELECTRE - Joao'!D4,'ELECTRE - Dante'!D4) - MIN('ELECTRE - Alif'!D4,'ELECTRE - Levente'!D4,'ELECTRE - Joao'!D4,'ELECTRE - Dante'!D4) -> 0 | G17: =MAX('ELECTRE - Alif'!E4,'ELECTRE - Levente'!E4,'ELECTRE - Joao'!E4,'ELECTRE - Dante'!E4) - MIN('ELECTRE - Alif'!E4,'ELECTRE - Levente'!E4,'ELECTRE - Joao'!E4,'ELECTRE - Dante'!E4) -> 1 | H17: =MAX('ELECTRE - Alif'!F4,'ELECTRE - Levente'!F4,'ELECTRE - Joao'!F4,'ELECTRE - Dante'!F4) - MIN('ELECTRE - Alif'!F4,'ELECTRE - Levente'!F4,'ELECTRE - Joao'!F4,'ELECTRE - Dante'!F4) -> 1 | I17: =MAX('ELECTRE - Alif'!G4,'ELECTRE - Levente'!G4,'ELECTRE - Joao'!G4,'ELECTRE - Dante'!G4) - MIN('ELECTRE - Alif'!G4,'ELECTRE - Levente'!G4,'ELECTRE - Joao'!G4,'ELECTRE - Dante'!G4) -> 1 | J17: =MAX('ELECTRE - Alif'!H4,'ELECTRE - Levente'!H4,'ELECTRE - Joao'!H4,'ELECTRE - Dante'!H4) - MIN('ELECTRE - Alif'!H4,'ELECTRE - Levente'!H4,'ELECTRE - Joao'!H4,'ELECTRE - Dante'!H4) -> 0 | K17: =MAX('ELECTRE - Alif'!I4,'ELECTRE - Levente'!I4,'ELECTRE - Joao'!I4,'ELECTRE - Dante'!I4) - MIN('ELECTRE - Alif'!I4,'ELECTRE - Levente'!I4,'ELECTRE - Joao'!I4,'ELECTRE - Dante'!I4) -> 0
D18: 3 | F18: =MAX('ELECTRE - Alif'!D5,'ELECTRE - Levente'!D5,'ELECTRE - Joao'!D5,'ELECTRE - Dante'!D5) - MIN('ELECTRE - Alif'!D5,'ELECTRE - Levente'!D5,'ELECTRE - Joao'!D5,'ELECTRE - Dante'!D5) -> 2 | G18: =MAX('ELECTRE - Alif'!E5,'ELECTRE - Levente'!E5,'ELECTRE - Joao'!E5,'ELECTRE - Dante'!E5) - MIN('ELECTRE - Alif'!E5,'ELECTRE - Levente'!E5,'ELECTRE - Joao'!E5,'ELECTRE - Dante'!E5) -> 2 | H18: =MAX('ELECTRE - Alif'!F5,'ELECTRE - Levente'!F5,'ELECTRE - Joao'!F5,'ELECTRE - Dante'!F5) - MIN('ELECTRE - Alif'!F5,'ELECTRE - Levente'!F5,'ELECTRE - Joao'!F5,'ELECTRE - Dante'!F5) -> 2 | I18: =MAX('ELECTRE - Alif'!G5,'ELECTRE - Levente'!G5,'ELECTRE - Joao'!G5,'ELECTRE - Dante'!G5) - MIN('ELECTRE - Alif'!G5,'ELECTRE - Levente'!G5,'ELECTRE - Joao'!G5,'ELECTRE - Dante'!G5) -> 0 | J18: =MAX('ELECTRE - Alif'!H5,'ELECTRE - Levente'!H5,'ELECTRE - Joao'!H5,'ELECTRE - Dante'!H5) - MIN('ELECTRE - Alif'!H5,'ELECTRE - Levente'!H5,'ELECTRE - Joao'!H5,'ELECTRE - Dante'!H5) -> 1 | K18: =MAX('ELECTRE - Alif'!I5,'ELECTRE - Levente'!I5,'ELECTRE - Joao'!I5,'ELECTRE - Dante'!I5) - MIN('ELECTRE - Alif'!I5,'ELECTRE - Levente'!I5,'ELECTRE - Joao'!I5,'ELECTRE - Dante'!I5) -> 0
D19: 9 | F19: =MAX('ELECTRE - Alif'!D6,'ELECTRE - Levente'!D6,'ELECTRE - Joao'!D6,'ELECTRE - Dante'!D6) - MIN('ELECTRE - Alif'!D6,'ELECTRE - Levente'!D6,'ELECTRE - Joao'!D6,'ELECTRE - Dante'!D6) -> 0 | G19: =MAX('ELECTRE - Alif'!E6,'ELECTRE - Levente'!E6,'ELECTRE - Joao'!E6,'ELECTRE - Dante'!E6) - MIN('ELECTRE - Alif'!E6,'ELECTRE - Levente'!E6,'ELECTRE - Joao'!E6,'ELECTRE - Dante'!E6) -> 0 | H19: =MAX('ELECTRE - Alif'!F6,'ELECTRE - Levente'!F6,'ELECTRE - Joao'!F6,'ELECTRE - Dante'!F6) - MIN('ELECTRE - Alif'!F6,'ELECTRE - Levente'!F6,'ELECTRE - Joao'!F6,'ELECTRE - Dante'!F6) -> 0 | I19: =MAX('ELECTRE - Alif'!G6,'ELECTRE - Levente'!G6,'ELECTRE - Joao'!G6,'ELECTRE - Dante'!G6) - MIN('ELECTRE - Alif'!G6,'ELECTRE - Levente'!G6,'ELECTRE - Joao'!G6,'ELECTRE - Dante'!G6) -> 2 | J19: =MAX('ELECTRE - Alif'!H6,'ELECTRE - Levente'!H6,'ELECTRE - Joao'!H6,'ELECTRE - Dante'!H6) - MIN('ELECTRE - Alif'!H6,'ELECTRE - Levente'!H6,'ELECTRE - Joao'!H6,'ELECTRE - Dante'!H6) -> 0 | K19: =MAX('ELECTRE - Alif'!I6,'ELECTRE - Levente'!I6,'ELECTRE - Joao'!I6,'ELECTRE - Dante'!I6) - MIN('ELECTRE - Alif'!I6,'ELECTRE - Levente'!I6,'ELECTRE - Joao'!I6,'ELECTRE - Dante'!I6) -> 0
D20: 10 | F20: =MAX('ELECTRE - Alif'!D7,'ELECTRE - Levente'!D7,'ELECTRE - Joao'!D7,'ELECTRE - Dante'!D7) - MIN('ELECTRE - Alif'!D7,'ELECTRE - Levente'!D7,'ELECTRE - Joao'!D7,'ELECTRE - Dante'!D7) -> 0 | G20: =MAX('ELECTRE - Alif'!E7,'ELECTRE - Levente'!E7,'ELECTRE - Joao'!E7,'ELECTRE - Dante'!E7) - MIN('ELECTRE - Alif'!E7,'ELECTRE - Levente'!E7,'ELECTRE - Joao'!E7,'ELECTRE - Dante'!E7) -> 1 | H20: =MAX('ELECTRE - Alif'!F7,'ELECTRE - Levente'!F7,'ELECTRE - Joao'!F7,'ELECTRE - Dante'!F7) - MIN('ELECTRE - Alif'!F7,'ELECTRE - Levente'!F7,'ELECTRE - Joao'!F7,'ELECTRE - Dante'!F7) -> 2 | I20: =MAX('ELECTRE - Alif'!G7,'ELECTRE - Levente'!G7,'ELECTRE - Joao'!G7,'ELECTRE - Dante'!G7) - MIN('ELECTRE - Alif'!G7,'ELECTRE - Levente'!G7,'ELECTRE - Joao'!G7,'ELECTRE - Dante'!G7) -> 1 | J20: =MAX('ELECTRE - Alif'!H7,'ELECTRE - Levente'!H7,'ELECTRE - Joao'!H7,'ELECTRE - Dante'!H7) - MIN('ELECTRE - Alif'!H7,'ELECTRE - Levente'!H7,'ELECTRE - Joao'!H7,'ELECTRE - Dante'!H7) -> 0 | K20: =MAX('ELECTRE - Alif'!I7,'ELECTRE - Levente'!I7,'ELECTRE - Joao'!I7,'ELECTRE - Dante'!I7) - MIN('ELECTRE - Alif'!I7,'ELECTRE - Levente'!I7,'ELECTRE - Joao'!I7,'ELECTRE - Dante'!I7) -> 0
D21: 11 | F21: =MAX('ELECTRE - Alif'!D8,'ELECTRE - Levente'!D8,'ELECTRE - Joao'!D8,'ELECTRE - Dante'!D8) - MIN('ELECTRE - Alif'!D8,'ELECTRE - Levente'!D8,'ELECTRE - Joao'!D8,'ELECTRE - Dante'!D8) -> 1 | G21: =MAX('ELECTRE - Alif'!E8,'ELECTRE - Levente'!E8,'ELECTRE - Joao'!E8,'ELECTRE - Dante'!E8) - MIN('ELECTRE - Alif'!E8,'ELECTRE - Levente'!E8,'ELECTRE - Joao'!E8,'ELECTRE - Dante'!E8) -> 2 | H21: =MAX('ELECTRE - Alif'!F8,'ELECTRE - Levente'!F8,'ELECTRE - Joao'!F8,'ELECTRE - Dante'!F8) - MIN('ELECTRE - Alif'!F8,'ELECTRE - Levente'!F8,'ELECTRE - Joao'!F8,'ELECTRE - Dante'!F8) -> 2 | I21: =MAX('ELECTRE - Alif'!G8,'ELECTRE - Levente'!G8,'ELECTRE - Joao'!G8,'ELECTRE - Dante'!G8) - MIN('ELECTRE - Alif'!G8,'ELECTRE - Levente'!G8,'ELECTRE - Joao'!G8,'ELECTRE - Dante'!G8) -> 1 | J21: =MAX('ELECTRE - Alif'!H8,'ELECTRE - Levente'!H8,'ELECTRE - Joao'!H8,'ELECTRE - Dante'!H8) - MIN('ELECTRE - Alif'!H8,'ELECTRE - Levente'!H8,'ELECTRE - Joao'!H8,'ELECTRE - Dante'!H8) -> 0 | K21: =MAX('ELECTRE - Alif'!I8,'ELECTRE - Levente'!I8,'ELECTRE - Joao'!I8,'ELECTRE - Dante'!I8) - MIN('ELECTRE - Alif'!I8,'ELECTRE - Levente'!I8,'ELECTRE - Joao'!I8,'ELECTRE - Dante'!I8) -> 0
D22: 12 | F22: =MAX('ELECTRE - Alif'!D9,'ELECTRE - Levente'!D9,'ELECTRE - Joao'!D9,'ELECTRE - Dante'!D9) - MIN('ELECTRE - Alif'!D9,'ELECTRE - Levente'!D9,'ELECTRE - Joao'!D9,'ELECTRE - Dante'!D9) -> 0 | G22: =MAX('ELECTRE - Alif'!E9,'ELECTRE - Levente'!E9,'ELECTRE - Joao'!E9,'ELECTRE - Dante'!E9) - MIN('ELECTRE - Alif'!E9,'ELECTRE - Levente'!E9,'ELECTRE - Joao'!E9,'ELECTRE - Dante'!E9) -> 3 | H22: =MAX('ELECTRE - Alif'!F9,'ELECTRE - Levente'!F9,'ELECTRE - Joao'!F9,'ELECTRE - Dante'!F9) - MIN('ELECTRE - Alif'!F9,'ELECTRE - Levente'!F9,'ELECTRE - Joao'!F9,'ELECTRE - Dante'!F9) -> 3 | I22: =MAX('ELECTRE - Alif'!G9,'ELECTRE - Levente'!G9,'ELECTRE - Joao'!G9,'ELECTRE - Dante'!G9) - MIN('ELECTRE - Alif'!G9,'ELECTRE - Levente'!G9,'ELECTRE - Joao'!G9,'ELECTRE - Dante'!G9) -> 0 | J22: =MAX('ELECTRE - Alif'!H9,'ELECTRE - Levente'!H9,'ELECTRE - Joao'!H9,'ELECTRE - Dante'!H9) - MIN('ELECTRE - Alif'!H9,'ELECTRE - Levente'!H9,'ELECTRE - Joao'!H9,'ELECTRE - Dante'!H9) -> 2 | K22: =MAX('ELECTRE - Alif'!I9,'ELECTRE - Levente'!I9,'ELECTRE - Joao'!I9,'ELECTRE - Dante'!I9) - MIN('ELECTRE - Alif'!I9,'ELECTRE - Levente'!I9,'ELECTRE - Joao'!I9,'ELECTRE - Dante'!I9) -> 0
D23: 13 | F23: =MAX('ELECTRE - Alif'!D10,'ELECTRE - Levente'!D10,'ELECTRE - Joao'!D10,'ELECTRE - Dante'!D10) - MIN('ELECTRE - Alif'!D10,'ELECTRE - Levente'!D10,'ELECTRE - Joao'!D10,'ELECTRE - Dante'!D10) -> 0 | G23: =MAX('ELECTRE - Alif'!E10,'ELECTRE - Levente'!E10,'ELECTRE - Joao'!E10,'ELECTRE - Dante'!E10) - MIN('ELECTRE - Alif'!E10,'ELECTRE - Levente'!E10,'ELECTRE - Joao'!E10,'ELECTRE - Dante'!E10) -> 1 | H23: =MAX('ELECTRE - Alif'!F10,'ELECTRE - Levente'!F10,'ELECTRE - Joao'!F10,'ELECTRE - Dante'!F10) - MIN('ELECTRE - Alif'!F10,'ELECTRE - Levente'!F10,'ELECTRE - Joao'!F10,'ELECTRE - Dante'!F10) -> 1 | I23: =MAX('ELECTRE - Alif'!G10,'ELECTRE - Levente'!G10,'ELECTRE - Joao'!G10,'ELECTRE - Dante'!G10) - MIN('ELECTRE - Alif'!G10,'ELECTRE - Levente'!G10,'ELECTRE - Joao'!G10,'ELECTRE - Dante'!G10) -> 1 | J23: =MAX('ELECTRE - Alif'!H10,'ELECTRE - Levente'!H10,'ELECTRE - Joao'!H10,'ELECTRE - Dante'!H10) - MIN('ELECTRE - Alif'!H10,'ELECTRE - Levente'!H10,'ELECTRE - Joao'!H10,'ELECTRE - Dante'!H10) -> 2 | K23: =MAX('ELECTRE - Alif'!I10,'ELECTRE - Levente'!I10,'ELECTRE - Joao'!I10,'ELECTRE - Dante'!I10) - MIN('ELECTRE - Alif'!I10,'ELECTRE - Levente'!I10,'ELECTRE - Joao'!I10,'ELECTRE - Dante'!I10) -> 0
D24: 16 | F24: =MAX('ELECTRE - Alif'!D11,'ELECTRE - Levente'!D11,'ELECTRE - Joao'!D11,'ELECTRE - Dante'!D11) - MIN('ELECTRE - Alif'!D11,'ELECTRE - Levente'!D11,'ELECTRE - Joao'!D11,'ELECTRE - Dante'!D11) -> 2 | G24: =MAX('ELECTRE - Alif'!E11,'ELECTRE - Levente'!E11,'ELECTRE - Joao'!E11,'ELECTRE - Dante'!E11) - MIN('ELECTRE - Alif'!E11,'ELECTRE - Levente'!E11,'ELECTRE - Joao'!E11,'ELECTRE - Dante'!E11) -> 1 | H24: =MAX('ELECTRE - Alif'!F11,'ELECTRE - Levente'!F11,'ELECTRE - Joao'!F11,'ELECTRE - Dante'!F11) - MIN('ELECTRE - Alif'!F11,'ELECTRE - Levente'!F11,'ELECTRE - Joao'!F11,'ELECTRE - Dante'!F11) -> 3 | I24: =MAX('ELECTRE - Alif'!G11,'ELECTRE - Levente'!G11,'ELECTRE - Joao'!G11,'ELECTRE - Dante'!G11) - MIN('ELECTRE - Alif'!G11,'ELECTRE - Levente'!G11,'ELECTRE - Joao'!G11,'ELECTRE - Dante'!G11) -> 0 | J24: =MAX('ELECTRE - Alif'!H11,'ELECTRE - Levente'!H11,'ELECTRE - Joao'!H11,'ELECTRE - Dante'!H11) - MIN('ELECTRE - Alif'!H11,'ELECTRE - Levente'!H11,'ELECTRE - Joao'!H11,'ELECTRE - Dante'!H11) -> 2 | K24: =MAX('ELECTRE - Alif'!I11,'ELECTRE - Levente'!I11,'ELECTRE - Joao'!I11,'ELECTRE - Dante'!I11) - MIN('ELECTRE - Alif'!I11,'ELECTRE - Levente'!I11,'ELECTRE - Joao'!I11,'ELECTRE - Dante'!I11) -> 0
D25: 18 | F25: =MAX('ELECTRE - Alif'!D12,'ELECTRE - Levente'!D12,'ELECTRE - Joao'!D12,'ELECTRE - Dante'!D12) - MIN('ELECTRE - Alif'!D12,'ELECTRE - Levente'!D12,'ELECTRE - Joao'!D12,'ELECTRE - Dante'!D12) -> 0 | G25: =MAX('ELECTRE - Alif'!E12,'ELECTRE - Levente'!E12,'ELECTRE - Joao'!E12,'ELECTRE - Dante'!E12) - MIN('ELECTRE - Alif'!E12,'ELECTRE - Levente'!E12,'ELECTRE - Joao'!E12,'ELECTRE - Dante'!E12) -> 2 | H25: =MAX('ELECTRE - Alif'!F12,'ELECTRE - Levente'!F12,'ELECTRE - Joao'!F12,'ELECTRE - Dante'!F12) - MIN('ELECTRE - Alif'!F12,'ELECTRE - Levente'!F12,'ELECTRE - Joao'!F12,'ELECTRE - Dante'!F12) -> 1 | I25: =MAX('ELECTRE - Alif'!G12,'ELECTRE - Levente'!G12,'ELECTRE - Joao'!G12,'ELECTRE - Dante'!G12) - MIN('ELECTRE - Alif'!G12,'ELECTRE - Levente'!G12,'ELECTRE - Joao'!G12,'ELECTRE - Dante'!G12) -> 2 | J25: =MAX('ELECTRE - Alif'!H12,'ELECTRE - Levente'!H12,'ELECTRE - Joao'!H12,'ELECTRE - Dante'!H12) - MIN('ELECTRE - Alif'!H12,'ELECTRE - Levente'!H12,'ELECTRE - Joao'!H12,'ELECTRE - Dante'!H12) -> 0 | K25: =MAX('ELECTRE - Alif'!I12,'ELECTRE - Levente'!I12,'ELECTRE - Joao'!I12,'ELECTRE - Dante'!I12) - MIN('ELECTRE - Alif'!I12,'ELECTRE - Levente'!I12,'ELECTRE - Joao'!I12,'ELECTRE - Dante'!I12) -> 0
D26: 20 | F26: =MAX('ELECTRE - Alif'!D13,'ELECTRE - Levente'!D13,'ELECTRE - Joao'!D13,'ELECTRE - Dante'!D13) - MIN('ELECTRE - Alif'!D13,'ELECTRE - Levente'!D13,'ELECTRE - Joao'!D13,'ELECTRE - Dante'!D13) -> 0 | G26: =MAX('ELECTRE - Alif'!E13,'ELECTRE - Levente'!E13,'ELECTRE - Joao'!E13,'ELECTRE - Dante'!E13) - MIN('ELECTRE - Alif'!E13,'ELECTRE - Levente'!E13,'ELECTRE - Joao'!E13,'ELECTRE - Dante'!E13) -> 2 | H26: =MAX('ELECTRE - Alif'!F13,'ELECTRE - Levente'!F13,'ELECTRE - Joao'!F13,'ELECTRE - Dante'!F13) - MIN('ELECTRE - Alif'!F13,'ELECTRE - Levente'!F13,'ELECTRE - Joao'!F13,'ELECTRE - Dante'!F13) -> 2 | I26: =MAX('ELECTRE - Alif'!G13,'ELECTRE - Levente'!G13,'ELECTRE - Joao'!G13,'ELECTRE - Dante'!G13) - MIN('ELECTRE - Alif'!G13,'ELECTRE - Levente'!G13,'ELECTRE - Joao'!G13,'ELECTRE - Dante'!G13) -> 2 | J26: =MAX('ELECTRE - Alif'!H13,'ELECTRE - Levente'!H13,'ELECTRE - Joao'!H13,'ELECTRE - Dante'!H13) - MIN('ELECTRE - Alif'!H13,'ELECTRE - Levente'!H13,'ELECTRE - Joao'!H13,'ELECTRE - Dante'!H13) -> 1 | K26: =MAX('ELECTRE - Alif'!I13,'ELECTRE - Levente'!I13,'ELECTRE - Joao'!I13,'ELECTRE - Dante'!I13) - MIN('ELECTRE - Alif'!I13,'ELECTRE - Levente'!I13,'ELECTRE - Joao'!I13,'ELECTRE - Dante'!I13) -> 0

Sheet Rank Key
B2: Rank | C2: Environmental Impact | D2: Cross-Bprder Connectivity & Network Integration | E2: Cost (CAPEX + O&M) | F2: Complexity/ Feasibility | G2: Socio Economic Benefits | H2: Safety & Resilience
B3: 5 | C3: Major GHG Reduction, enables substantial modal shift (e.g shifts road use into electrified rail) | D3: Eliminates critical cross-border bottleneck at the EU level | E3: Very low capex (road upgrades) with low O&M cost (estimated < 1 billion Euros) | F3: Low Complexity, upgrades to existing facility that would require <2 years to complete | G3: Regional Development/ job creation, cohesion in less develoed region, improved accessibility for many citizens (EU level) | H3: Major improvements in transport safety, climate resilience and infrastructure security
B4: 4 | C4: Significant Reduction in pollutants due to nodal shift but cannot be achieved without some environmental tradeoff | D4: Provides meaningful cross-border or interregional linkage at the EU level | E4: Moderate CAPEX (Rail upgrade, airport creation) - (1-3 billion Euros) | F4: Medium engineering complexity (rail & ground tunnel creation, etc.), requiring less than a decade to complete (2-5 years) | G4: Strong benefits with clear regional spillover effect | H4: Major improvements in either safety or resilience in EU level
B5: 3 | C5: Upgrades that results in moderate Reduction; contributes indirectly (e.g improves efficiency thus less CO2 or supports electrification) | D5: Improves connectivity at the national/ regional level. Connects between 2 countries and improves EU connectivity | E5: Medium CAPEX (Rail Creation) - (3-6 billion Euros) | F5: Medium engineering complexity (rail & ground tunnel creation, etc.), requiring less than a decade to complete (5-10 years) | G5: Benefits mainly in the local/ regional level. Offers long-term jobs though limited to a region | H5: Moderate improvements in either safety or resilience in EU level
B6: 2 | C6: Limited positive environmental effects. Potential increase in emissions, but some effort to control emissions (carbon accreditation, sustainability reporting etc.) | D6: Connectivity gains at the local level. Mostly improves connectivity of one country, with indirect connectivity imrovement across EU (e.g easier accesibility to existing networks) | E6: Very High CAPEX or high maintenance (estimated 6-10 billion Euros) | F6: High engineering complexity (underwater tunneling, etc), OR encompassing multiple countries in scope and would require decades to complete (>10 years) | G6: marginal & localized benefits with limited impact. Offers time-limited jobs usually related to construction | H6: Contributions in either safety or resilience in the local/ regional level
B7: 1 | C7: No measurable environmental benefit/ risk of negative impact | D7: No added value for EU-level integration. Improves connectivity for a country only, no EU benefit | E7: Very High CAPEX (Tunneling) and high maintenance (estimated > 10 billion Euros) | F7: High engineering complexity (under water tunneling, etc.), AND encompassing multiple countries in scope and would require decades to complete (>10 years) | G7: no significant contribution | H7: No improvement or potential risk unaddressed

Sheet Electre csv
A1: Scenario no. | B1: Scenarios | C1: Environmental Impact | D1: Cross-Border Connectivity & Network Integration | E1: Cost (CAPEX + O&M) | F1: Complexity/ Feasibility | G1: Socio Economic Benefits | H1: Safety & Resilience
A2: 1 | B2: SC1 | C2: 4 | D2: 4 | E2: 2 | F2: 1 | G2: 5 | H2: 4
A3: 3 | B3: SC3 | C3: 4 | D3: 3 | E3: 4 | F3: 3 | G3: 3 | H3: 3
A4: 9 | B4: SC9 | C4: 3 | D4: 5 | E4: 1 | F4: 2 | G4: 4 | H4: 3
A5: 10 | B5: SC10 | C5: 3 | D5: 4 | E5: 3 | F5: 3 | G5: 4 | H5: 3
A6: 11 | B6: SC11 | C6: 3 | D6: 1 | E6: 4 | F6: 4 | G6: 3 | H6: 3
A7: 12 | B7: SC12 | C7: 3 | D7: 2 | E7: 5 | F7: 3 | G7: 3 | H7: 4
A8: 13 | B8: SC13 | C8: 4 | D8: 1 | E8: 5 | F8: 5 | G8: 2 | H8: 3
A9: 16 | B9: SC16 | C9: 3 | D9: 2 | E9: 4 | F9: 2 | G9: 3 | H9: 4
A10: 18 | B10: SC18 | C10: 4 | D10: 5 | E10: 3 | F10: 2 | G10: 5 | H10: 4
A11: 20 | B11: SC20 | C11: 3 | D11: 4 | E11: 5 | F11: 3 | G11: 5 | H11: 3

Sheet Ranking csv
A1: Weight | B1: Scenarios
A2: 4 | B2: Environmental Impact
A3: 8 | B3: Cross-Border Connectivity & Network Integration
A4: 6 | B4: Cost (CAPEX + O&M)
A5: 4 | B5: Complexity/ Feasibility
A6: 9 | B6: Socio Economic Benefits
A7: 2 | B7: Safety & Resilience

Sheet Outranking Graph Result

Sheet MCDA - AHP
P2: AHP
P4: Social | AA4: Environmental | AL4: Economic
O6: C5 | P6: Labour market and sociographic job distribution | Z6: C3 | AA6: Ecosystem and biodiversity loss | AK6: C1 | AL6: Integration of European transport | BH6: Geometric Mean Scores
BE7: Criteria | BG7: Weights | BH7: SC1 | BI7: SC10 | BJ7: SC18 | BK7: SC20
P8: Weights | Q8: 0.1 | AA8: Weights | AB8: 0.15 | AL8: Weights | AM8: 0.3 | BE8: Social | BF8: Labour market and sociographic job distribution | BG8: =BC14 -> 0.010865979 | BH8: =$V$10 -> 0.21627078 | BI8: =$V$11 -> 0.12378412 | BJ8: =$V$12 -> 0.63406145 | BK8: =$V$13 -> 0.025883653
Q9: SC1 | R9: SC10 | S9: SC18 | T9: SC20 | V9: Score (Geometric Mean) | AB9: SC1 | AC9: SC10 | AD9: SC18 | AE9: SC20 | AG9: Score (Geometric Mean) | AM9: SC1 | AN9: SC10 | AO9: SC18 | AP9: SC20 | AR9: Score (Geometric Mean) | AV9: C1 | AW9: C2 | AX9: C3 | AY9: C4 | AZ9: C5 | BA9: C6 | BC9: Score (Geometric Mean) | BE9: Social | BF9: Territorial cohesion | BG9: =BC15 -> 0.010865979 | BH9: =$V$28 -> 0.51416558 | BI9: =$V$29 -> 0.32390402 | BJ9: =$V$30 -> 0.12628015 | BK9: =$V$31 -> 0.03565025
P10: SC1 | Q10: ='MCDA - Social'!J5 -> 1 | R10: ='MCDA - Social'!K5 -> 2 | S10: ='MCDA - Social'!L5 -> 0.33333333 | T10: ='MCDA - Social'!M5 -> 5 | U10: =(Q10*R10*S10*T10)^(1/3) -> 1.4938016 | V10: =U10/SUM($U$10:$U$13) -> 0.21627078 | AA10: SC1 | AB10: 1 | AC10: 3 | AD10: 0.333333 | AE10: 0.2 | AF10: =(AB10*AC10*AD10*AE10)^(1/3) -> 0.58480335 | AG10: =AF10/SUM($AF$10:$AF$13) -> 0.076749463 | AL10: SC1 | AM10: ='MCDA - Economic'!W27 -> 1 | AN10: ='MCDA - Economic'!X27 -> 5 | AO10: ='MCDA - Economic'!Y27 -> 0.33333333 | AP10: ='MCDA - Economic'!Z27 -> 0.33333333 | AQ10: =(AM10*AN10*AO10*AP10)^(1/3) -> 0.82207069 | AR10: =AQ10/SUM($AQ$10:$AQ$13) -> 0.12366299 | AU10: C1 | AV10: 1 | AW10: 2 | AX10: 5 | AY10: 6 | AZ10: 6 | BA10: 6 | BB10: =(AX10*AY10*AZ10*BA10*AW10*AV10)^(1/3) -> 12.926608 | BC10: =BB10/SUM($BB$10:$BB$15) -> 0.62945924 | BE10: Environmental | BF10: Ecosystem and biodiversity loss | BG10: =BC12 -> 0.059234382 | BH10: =$AG$10 -> 0.076749463 | BI10: =$AG$11 -> 0.025583146 | BJ10: =$AG$12 -> 0.22441679 | BK10: =$AG$13 -> 0.6732506
P11: SC10 | Q11: ='MCDA - Social'!J6 -> 0.5 | R11: ='MCDA - Social'!K6 -> 1 | S11: ='MCDA - Social'!L6 -> 0.25 | T11: ='MCDA - Social'!M6 -> 5 | U11: =(Q11*R11*S11*T11)^(1/3) -> 0.85498797 | V11: =U11/SUM($U$10:$U$13) -> 0.12378412 | AA11: SC10 | AB11: 0.333333 | AC11: 1 | AD11: 0.2 | AE11: 0.111111 | AF11: =(AB11*AC11*AD11*AE11)^(1/3) -> 0.19493439 | AG11: =AF11/SUM($AF$10:$AF$13) -> 0.025583146 | AL11: SC10 | AM11: ='MCDA - Economic'!W28 -> 0.2 | AN11: ='MCDA - Economic'!X28 -> 1 | AO11: ='MCDA - Economic'!Y28 -> 0.14285714 | AP11: ='MCDA - Economic'!Z28 -> 0.14285714 | AQ11: =(AM11*AN11*AO11*AP11)^(1/3) -> 0.15981271 | AR11: =AQ11/SUM($AQ$10:$AQ$13) -> 0.02404041 | AU11: C2 | AV11: =1/AW10 -> 0.5 | AW11: 1 | AX11: 3 | AY11: 5 | AZ11: 5 | BA11: 5 | BB11: =(AX11*AY11*AZ11*BA11*AW11*AV11)^(1/3) -> 5.7235712 | BC11: =BB11/SUM($BB$10:$BB$15) -> 0.27870844 | BE11: Environmental | BF11: Non-renewable dependance | BG11: =BC13 -> 0.010865979 | BH11: =$AG$28 -> 0.67374603 | BI11: =$AG$29 -> 0.032609169 | BJ11: =$AG$30 -> 0.19804135 | BK11: =$AG$31 -> 0.095603444
P12: SC18 | Q12: ='MCDA - Social'!J7 -> 3 | R12: ='MCDA - Social'!K7 -> 4 | S12: ='MCDA - Social'!L7 -> 1 | T12: ='MCDA - Social'!M7 -> 7 | U12: =(Q12*R12*S12*T12)^(1/3) -> 4.3795191 | V12: =U12/SUM($U$10:$U$13) -> 0.63406145 | AA12: SC18 | AB12: 3 | AC12: 5 | AD12: 1 | AE12: 0.333333 | AF12: =(AB12*AC12*AD12*AE12)^(1/3) -> 1.7099754 | AG12: =AF12/SUM($AF$10:$AF$13) -> 0.22441679 | AL12: SC18 | AM12: ='MCDA - Economic'!W29 -> 3 | AN12: ='MCDA - Economic'!X29 -> 7 | AO12: ='MCDA - Economic'!Y29 -> 1 | AP12: ='MCDA - Economic'!Z29 -> 0.5 | AQ12: =(AM12*AN12*AO12*AP12)^(1/3) -> 2.1897596 | AR12: =AQ12/SUM($AQ$10:$AQ$13) -> 0.32940259 | AU12: C3 | AV12: =1/AX10 -> 0.2 | AW12: =1/AX11 -> 0.33333333 | AX12: 1 | AY12: 3 | AZ12: 3 | BA12: 3 | BB12: =(AX12*AY12*AZ12*BA12*AW12*AV12)^(1/3) -> 1.2164404 | BC12: =BB12/SUM($BB$10:$BB$15) -> 0.059234382 | BE12: Economic | BF12: Integration of European transport | BG12: =BC10 -> 0.62945924 | BH12: =$AR$10 -> 0.12366299 | BI12: =$AR$11 -> 0.02404041 | BJ12: =$AR$12 -> 0.32940259 | BK12: =$AR$13 -> 0.52289401
P13: SC20 | Q13: ='MCDA - Social'!J8 -> 0.2 | R13: ='MCDA - Social'!K8 -> 0.2 | S13: ='MCDA - Social'!L8 -> 0.14285714 | T13: ='MCDA - Social'!M8 -> 1 | U13: =(Q13*R13*S13*T13)^(1/3) -> 0.17878071 | V13: =U13/SUM($U$10:$U$13) -> 0.025883653 | AA13: SC20 | AB13: 5 | AC13: 9 | AD13: 3 | AE13: 1 | AF13: =(AB13*AC13*AD13*AE13)^(1/3) -> 5.1299278 | AG13: =AF13/SUM($AF$10:$AF$13) -> 0.6732506 | AL13: SC20 | AM13: ='MCDA - Economic'!W30 -> 3 | AN13: ='MCDA - Economic'!X30 -> 7 | AO13: ='MCDA - Economic'!Y30 -> 2 | AP13: ='MCDA - Economic'!Z30 -> 1 | AQ13: =(AM13*AN13*AO13*AP13)^(1/3) -> 3.4760266 | AR13: =AQ13/SUM($AQ$10:$AQ$13) -> 0.52289401 | AU13: C4 | AV13: =1/AY10 -> 0.16666667 | AW13: =1/AY11 -> 0.2 | AX13: =1/AY12 -> 0.33333333 | AY13: 1 | AZ13: 1 | BA13: 1 | BB13: =(AX13*AY13*AZ13*BA13*AW13*AV13)^(1/3) -> 0.22314432 | BC13: =BB13/SUM($BB$10:$BB$15) -> 0.010865979 | BE13: Economic | BF13: Location of companies and logistic centers | BG13: =BC11 -> 0.27870844 | BH13: =$AR$28 -> 0.10225757 | BI13: =$AR$29 -> 0.026727979 | BJ13: =$AR$30 -> 0.56424175 | BK13: =$AR$31 -> 0.3067727
P14: Sum | Q14: =SUM(Q10:Q13) -> 4.7 | R14: =SUM(R10:R13) -> 7.2 | S14: =SUM(S10:S13) -> 1.7261905 | T14: =SUM(T10:T13) -> 18 | V14: =SUM(V10:V13) -> 1 | AA14: Sum | AB14: =SUM(AB10:AB13) -> 9.333333 | AC14: =SUM(AC10:AC13) -> 18 | AD14: =SUM(AD10:AD13) -> 4.533333 | AE14: =SUM(AE10:AE13) -> 1.644444 | AG14: =SUM(AG10:AG13) -> 1 | AL14: Sum | AM14: =SUM(AM10:AM13) -> 7.2 | AN14: =SUM(AN10:AN13) -> 20 | AO14: =SUM(AO10:AO13) -> 3.4761905 | AP14: =SUM(AP10:AP13) -> 1.9761905 | AR14: =SUM(AR10:AR13) -> 1 | AU14: C5 | AV14: =1/AZ10 -> 0.16666667 | AW14: =1/AZ11 -> 0.2 | AX14: =1/AZ12 -> 0.33333333 | AY14: =1/AZ13 -> 1 | AZ14: 1 | BA14: 1 | BB14: =(AX14*AY14*AZ14*BA14*AW14*AV14)^(1/3) -> 0.22314432 | BC14: =BB14/SUM($BB$10:$BB$15) -> 0.010865979 | BG14: AHP Score | BH14: =($BG$8*BH8)+($BG$9*BH9)+($BG$10*BH10)+($BG$11*BH11)+($BG$12+BH12)+($BG$13*BH13) -> 0.8014263 | BI14: =($BG$8*BI8)+($BG$9*BI9)+($BG$10*BI10)+($BG$11*BI11)+($BG$12+BI12)+($BG$13*BI13) -> 0.66768327 | BJ14: =($BG$8*BJ8)+($BG$9*BJ9)+($BG$10*BJ10)+($BG$11*BJ11)+($BG$12+BJ12)+($BG$13*BJ13) -> 1.1398277 | BK14: =($BG$8*BK8)+($BG$9*BK9)+($BG$10*BK10)+($BG$11*BK11)+($BG$12+BK12)+($BG$13*BK13) -> 1.2794404
AU15: C6 | AV15: =1/BA10 -> 0.16666667 | AW15: =1/BA11 -> 0.2 | AX15: =1/BA12 -> 0.33333333 | AY15: =1/BA13 -> 1 | AZ15: =1/BA14 -> 1 | BA15: 1 | BB15: =(AX15*AY15*AZ15*BA15*AW15*AV15)^(1/3) -> 0.22314432 | BC15: =BB15/SUM($BB$10:$BB$15) -> 0.010865979 | BG15: Normalized | BH15: =BH14*100/SUM($BH$14:$BK$14) -> 20.610814 | BI15: =BI14*100/SUM($BH$14:$BK$14) -> 17.171255 | BJ15: =BJ14*100/SUM($BH$14:$BK$14) -> 29.313709 | BK15: =BK14*100/SUM($BH$14:$BK$14) -> 32.904222
Q16: SC1 | R16: SC10 | S16: SC18 | T16: SC20 | U16: Avg | V16: Lambda | W16: CI | AB16: SC1 | AC16: SC10 | AD16: SC18 | AE16: SC20 | AF16: Avg | AG16: Lambda | AH16: CI | AM16: SC1 | AN16: SC10 | AO16: SC18 | AP16: SC20 | AQ16: Avg | AR16: Lambda | AS16: CI | AU16: Sum | AV16: =SUM(AV10:AV15) -> 2.2 | AW16: =SUM(AW10:AW15) -> 3.9333333 | AX16: =SUM(AX10:AX15) -> 10 | AY16: =SUM(AY10:AY15) -> 17 | AZ16: =SUM(AZ10:AZ15) -> 17 | BA16: =SUM(BA10:BA15) -> 17 | BC16: =SUM(BC10:BC15) -> 1
P17: SC1 | Q17: =Q10/Q$14 -> 0.21276596 | R17: =R10/R$14 -> 0.27777778 | S17: =S10/S$14 -> 0.19310345 | T17: =T10/T$14 -> 0.27777778 | U17: =AVERAGE(Q17:T17) -> 0.24035624 | V17: {=MMULT(Q10:T10,U17:U20)/U17} -> 4.2240316 | W17: =(V22-4)/3 -> 0.08173434 | AA17: SC1 | AB17: =AB10/AB$14 -> 0.10714286 | AC17: =AC10/AC$14 -> 0.16666667 | AD17: =AD10/AD$14 -> 0.073529344 | AE17: =AE10/AE$14 -> 0.12162165 | AF17: =AVERAGE(AB17:AE17) -> 0.11724013 | AG17: {=MMULT(AB10:AE10,AF17:AF20)/AF17} -> 4.0083863 | AH17: =(AG22-4)/3 -> 0.046571924 | AL17: SC1 | AM17: =AM10/AM$14 -> 0.13888889 | AN17: =AN10/AN$14 -> 0.25 | AO17: =AO10/AO$14 -> 0.095890411 | AP17: =AP10/AP$14 -> 0.1686747 | AQ17: =AVERAGE(AM17:AP17) -> 0.1633635 | AR17: {=MMULT(AM10:AP10,AQ17:AQ20)/AQ17} -> 4.0723027 | AS17: =(AR22-4)/3 -> 0.076610077
P18: SC10 | Q18: =Q11/Q$14 -> 0.10638298 | R18: =R11/R$14 -> 0.13888889 | S18: =S11/S$14 -> 0.14482759 | T18: =T11/T$14 -> 0.27777778 | U18: =AVERAGE(Q18:T18) -> 0.16696931 | V18: {=MMULT(Q11:T11,U17:U20)/U18} -> 4.0910642 | AA18: SC10 | AB18: =AB11/AB$14 -> 0.035714251 | AC18: =AC11/AC$14 -> 0.055555556 | AD18: =AD11/AD$14 -> 0.04411765 | AE18: =AE11/AE$14 -> 0.067567518 | AF18: =AVERAGE(AB18:AE18) -> 0.050738744 | AG18: {=MMULT(AB11:AE11,AF17:AF20)/AF18} -> 4.0400613 | AL18: SC10 | AM18: =AM11/AM$14 -> 0.027777778 | AN18: =AN11/AN$14 -> 0.05 | AO18: =AO11/AO$14 -> 0.04109589 | AP18: =AP11/AP$14 -> 0.072289157 | AQ18: =AVERAGE(AM18:AP18) -> 0.047790706 | AR18: {=MMULT(AM11:AP11,AQ17:AQ20)/AQ18} -> 4.0416993 | AV18: C1 | AW18: C2 | AX18: C3 | AY18: C4 | AZ18: C5 | BA18: C6 | BB18: Avg | BC18: Lambda | BD18: CI
P19: SC18 | Q19: =Q12/Q$14 -> 0.63829787 | R19: =R12/R$14 -> 0.55555556 | S19: =S12/S$14 -> 0.57931034 | T19: =T12/T$14 -> 0.38888889 | U19: =AVERAGE(Q19:T19) -> 0.54051317 | V19: {=MMULT(Q12:T12,U17:U20)/U19} -> 4.245203 | AA19: SC18 | AB19: =AB12/AB$14 -> 0.32142858 | AC19: =AC12/AC$14 -> 0.27777778 | AD19: =AD12/AD$14 -> 0.22058825 | AE19: =AE12/AE$14 -> 0.20270255 | AF19: =AVERAGE(AB19:AE19) -> 0.25562429 | AG19: {=MMULT(AB12:AE12,AF17:AF20)/AF19} -> 4.1199938 | AL19: SC18 | AM19: =AM12/AM$14 -> 0.41666667 | AN19: =AN12/AN$14 -> 0.35 | AO19: =AO12/AO$14 -> 0.28767123 | AP19: =AP12/AP$14 -> 0.25301205 | AQ19: =AVERAGE(AM19:AP19) -> 0.32683749 | AR19: {=MMULT(AM12:AP12,AQ17:AQ20)/AQ19} -> 4.2298302 | AU19: C1 | AV19: =AV10/AV$16 -> 0.45454545 | AW19: =AW10/AW$16 -> 0.50847458 | AX19: =AX10/AX$16 -> 0.5 | AY19: =AY10/AY$16 -> 0.35294118 | AZ19: =AZ10/AZ$16 -> 0.35294118 | BA19: =BA10/BA$16 -> 0.35294118 | BB19: =AVERAGE(AV19:BA19) -> 0.42030726 | BC19: {=MMULT(AV10:BA10,$BB$19:$BB$24)/BB19} -> 6.316912 | BD19: =(BC26-6)/5 -> 0.063382393
P20: SC20 | Q20: =Q13/Q$14 -> 0.042553191 | R20: =R13/R$14 -> 0.027777778 | S20: =S13/S$14 -> 0.082758621 | T20: =T13/T$14 -> 0.055555556 | U20: =AVERAGE(Q20:T20) -> 0.052161286 | V20: {=MMULT(Q13:T13,U17:U20)/U20} -> 4.0421274 | AA20: SC20 | AB20: =AB13/AB$14 -> 0.5357143 | AC20: =AC13/AC$14 -> 0.5 | AD20: =AD13/AD$14 -> 0.66176475 | AE20: =AE13/AE$14 -> 0.60810827 | AF20: =AVERAGE(AB20:AE20) -> 0.57639683 | AG20: {=MMULT(AB13:AE13,AF17:AF20)/AF20} -> 4.1397158 | AL20: SC20 | AM20: =AM13/AM$14 -> 0.41666667 | AN20: =AN13/AN$14 -> 0.35 | AO20: =AO13/AO$14 -> 0.57534247 | AP20: =AP13/AP$14 -> 0.5060241 | AQ20: =AVERAGE(AM20:AP20) -> 0.46200831 | AR20: {=MMULT(AM13:AP13,AQ17:AQ20)/AQ20} -> 4.1997269 | AU20: C2 | AV20: =AV11/AV$16 -> 0.22727273 | AW20: =AW11/AW$16 -> 0.25423729 | AX20: =AX11/AX$16 -> 0.3 | AY20: =AY11/AY$16 -> 0.29411765 | AZ20: =AZ11/AZ$16 -> 0.29411765 | BA20: =BA11/BA$16 -> 0.29411765 | BB20: =AVERAGE(AV20:BA20) -> 0.27731049 | BC20: {=MMULT(AV11:BA11,$BB$19:$BB$24)/BB20} -> 6.2421721
P21: Sum | Q21: =SUM(Q17:Q20) -> 1 | R21: =SUM(R17:R20) -> 1 | S21: =SUM(S17:S20) -> 1 | T21: =SUM(T17:T20) -> 1 | U21: =SUM(U17:U20) -> 1 | AA21: Sum | AB21: =SUM(AB17:AB20) -> 1 | AC21: =SUM(AC17:AC20) -> 1 | AD21: =SUM(AD17:AD20) -> 1 | AE21: =SUM(AE17:AE20) -> 1 | AF21: =SUM(AF17:AF20) -> 1 | AL21: Sum | AM21: =SUM(AM17:AM20) -> 1 | AN21: =SUM(AN17:AN20) -> 1 | AO21: =SUM(AO17:AO20) -> 1 | AP21: =SUM(AP17:AP20) -> 1 | AQ21: =SUM(AQ17:AQ20) -> 1 | AU21: C3 | AV21: =AV12/AV$16 -> 0.090909091 | AW21: =AW12/AW$16 -> 0.084745763 | AX21: =AX12/AX$16 -> 0.1 | AY21: =AY12/AY$16 -> 0.17647059 | AZ21: =AZ12/AZ$16 -> 0.17647059 | BA21: =BA12/BA$16 -> 0.17647059 | BB21: =AVERAGE(AV21:BA21) -> 0.13417777 | BC21: {=MMULT(AV12:BA12,$BB$19:$BB$24)/BB21} -> 6.076189
U22: Lambda max | V22: =MAX(V17:V20) -> 4.245203 | AF22: Lambda max | AG22: =MAX(AG17:AG20) -> 4.1397158 | AQ22: Lambda max | AR22: =MAX(AR17:AR20) -> 4.2298302 | AU22: C4 | AV22: =AV13/AV$16 -> 0.075757576 | AW22: =AW13/AW$16 -> 0.050847458 | AX22: =AX13/AX$16 -> 0.033333333 | AY22: =AY13/AY$16 -> 0.058823529 | AZ22: =AZ13/AZ$16 -> 0.058823529 | BA22: =BA13/BA$16 -> 0.058823529 | BB22: =AVERAGE(AV22:BA22) -> 0.056068159 | BC22: {=MMULT(AV13:BA13,$BB$19:$BB$24)/BB22} -> 6.0362907
AU23: C5 | AV23: =AV14/AV$16 -> 0.075757576 | AW23: =AW14/AW$16 -> 0.050847458 | AX23: =AX14/AX$16 -> 0.033333333 | AY23: =AY14/AY$16 -> 0.058823529 | AZ23: =AZ14/AZ$16 -> 0.058823529 | BA23: =BA14/BA$16 -> 0.058823529 | BB23: =AVERAGE(AV23:BA23) -> 0.056068159 | BC23: {=MMULT(AV14:BA14,$BB$19:$BB$24)/BB23} -> 6.0362907
O24: C6 | P24: Territorial cohesion | Z24: C4 | AA24: Non-renewable dependance | AK24: C2 | AL24: Location of companies and logistic centers | AU24: C6 | AV24: =AV15/AV$16 -> 0.075757576 | AW24: =AW15/AW$16 -> 0.050847458 | AX24: =AX15/AX$16 -> 0.033333333 | AY24: =AY15/AY$16 -> 0.058823529 | AZ24: =AZ15/AZ$16 -> 0.058823529 | BA24: =BA15/BA$16 -> 0.058823529 | BB24: =AVERAGE(AV24:BA24) -> 0.056068159 | BC24: {=MMULT(AV15:BA15,$BB$19:$BB$24)/BB24} -> 6.0362907
AU25: Sum | AV25: =SUM(AV19:AV24) -> 1 | AW25: =SUM(AW19:AW24) -> 1 | AX25: =SUM(AX19:AX24) -> 1 | AY25: =SUM(AY19:AY24) -> 1 | AZ25: =SUM(AZ19:AZ24) -> 1 | BA25: =SUM(BA19:BA24) -> 1 | BB25: =SUM(BB19:BB24) -> 1
P26: Weights | Q26: =1-(Q8+AB8+AB26+AM8+AM26) -> 0.1 | AA26: Weights | AB26: 0.1 | AL26: Weights | AM26: 0.25 | BB26: Lambda max | BC26: =MAX(BC19:BC24) -> 6.316912
Q27: SC1 | R27: SC10 | S27: SC18 | T27: SC20 | V27: Score (Geometric Mean) | AB27: SC1 | AC27: SC10 | AD27: SC18 | AE27: SC20 | AG27: Score (Geometric Mean) | AM27: SC1 | AN27: SC10 | AO27: SC18 | AP27: SC20 | AR27: Score (Geometric Mean)
P28: SC1 | Q28: ='MCDA - Social'!J12 -> 1 | R28: ='MCDA - Social'!K12 -> 2 | S28: ='MCDA - Social'!L12 -> 3 | T28: ='MCDA - Social'!M12 -> 5 | U28: =(Q28*R28*S28*T28)^(1/3) -> 3.1072325 | V28: =U28/SUM($U$28:$U$31) -> 0.51416558 | AA28: SC1 | AB28: 1 | AC28: 7 | AD28: 3 | AE28: 5 | AF28: =(AB28*AC28*AD28*AE28)^(1/3) -> 4.717694 | AG28: =AF28/SUM($AF$28:$AF$31) -> 0.67374603 | AL28: SC1 | AM28: ='MCDA - Economic'!W53 -> 1 | AN28: ='MCDA - Economic'!X53 -> 4 | AO28: ='MCDA - Economic'!Y53 -> 0.25 | AP28: ='MCDA - Economic'!Z53 -> 0.33333333 | AQ28: =(AM28*AN28*AO28*AP28)^(1/3) -> 0.69336127 | AR28: =AQ28/SUM($AQ$28:$AQ$31) -> 0.10225757
P29: SC10 | Q29: ='MCDA - Social'!J13 -> 0.5 | R29: ='MCDA - Social'!K13 -> 1 | S29: ='MCDA - Social'!L13 -> 3 | T29: ='MCDA - Social'!M13 -> 5 | U29: =(Q29*R29*S29*T29)^(1/3) -> 1.9574338 | V29: =U29/SUM($U$28:$U$31) -> 0.32390402 | AA29: SC10 | AB29: 0.142857 | AC29: 1 | AD29: 0.25 | AE29: 0.333333 | AF29: =(AB29*AC29*AD29*AE29)^(1/3) -> 0.22833542 | AG29: =AF29/SUM($AF$28:$AF$31) -> 0.032609169 | AL29: SC10 | AM29: ='MCDA - Economic'!W54 -> 0.25 | AN29: ='MCDA - Economic'!X54 -> 1 | AO29: ='MCDA - Economic'!Y54 -> 0.14285714 | AP29: ='MCDA - Economic'!Z54 -> 0.16666667 | AQ29: =(AM29*AN29*AO29*AP29)^(1/3) -> 0.18123006 | AR29: =AQ29/SUM($AQ$28:$AQ$31) -> 0.026727979
P30: SC18 | Q30: ='MCDA - Social'!J14 -> 0.33333333 | R30: ='MCDA - Social'!K14 -> 0.33333333 | S30: ='MCDA - Social'!L14 -> 1 | T30: ='MCDA - Social'!M14 -> 4 | U30: =(Q30*R30*S30*T30)^(1/3) -> 0.76314283 | V30: =U30/SUM($U$28:$U$31) -> 0.12628015 | AA30: SC18 | AB30: 0.333333 | AC30: 4 | AD30: 1 | AE30: 2 | AF30: =(AB30*AC30*AD30*AE30)^(1/3) -> 1.3867221 | AG30: =AF30/SUM($AF$28:$AF$31) -> 0.19804135 | AL30: SC18 | AM30: ='MCDA - Economic'!W55 -> 4 | AN30: ='MCDA - Economic'!X55 -> 7 | AO30: ='MCDA - Economic'!Y55 -> 1 | AP30: ='MCDA - Economic'!Z55 -> 2 | AQ30: =(AM30*AN30*AO30*AP30)^(1/3) -> 3.8258624 | AR30: =AQ30/SUM($AQ$28:$AQ$31) -> 0.56424175
P31: SC20 | Q31: ='MCDA - Social'!J15 -> 0.2 | R31: ='MCDA - Social'!K15 -> 0.2 | S31: ='MCDA - Social'!L15 -> 0.25 | T31: ='MCDA - Social'!M15 -> 1 | U31: =(Q31*R31*S31*T31)^(1/3) -> 0.21544347 | V31: =U31/SUM($U$28:$U$31) -> 0.03565025 | AA31: SC20 | AB31: 0.2 | AC31: 3 | AD31: 0.5 | AE31: 1 | AF31: =(AB31*AC31*AD31*AE31)^(1/3) -> 0.66943295 | AG31: =AF31/SUM($AF$28:$AF$31) -> 0.095603444 | AL31: SC20 | AM31: ='MCDA - Economic'!W56 -> 3 | AN31: ='MCDA - Economic'!X56 -> 6 | AO31: ='MCDA - Economic'!Y56 -> 0.5 | AP31: ='MCDA - Economic'!Z56 -> 1 | AQ31: =(AM31*AN31*AO31*AP31)^(1/3) -> 2.0800838 | AR31: =AQ31/SUM($AQ$28:$AQ$31) -> 0.3067727
P32: Sum | Q32: =SUM(Q28:Q31) -> 2.0333333 | R32: =SUM(R28:R31) -> 3.5333333 | S32: =SUM(S28:S31) -> 7.25 | T32: =SUM(T28:T31) -> 15 | V32: =SUM(V28:V31) -> 1 | AA32: Sum | AB32: =SUM(AB28:AB31) -> 1.67619 | AC32: =SUM(AC28:AC31) -> 15 | AD32: =SUM(AD28:AD31) -> 4.75 | AE32: =SUM(AE28:AE31) -> 8.333333 | AG32: =SUM(AG28:AG31) -> 1 | AL32: Sum | AM32: =SUM(AM28:AM31) -> 8.25 | AN32: =SUM(AN28:AN31) -> 18 | AO32: =SUM(AO28:AO31) -> 1.8928571 | AP32: =SUM(AP28:AP31) -> 3.5 | AR32: =SUM(AR28:AR31) -> 1
Q34: SC1 | R34: SC10 | S34: SC18 | T34: SC20 | U34: Avg | V34: Lambda | W34: CI | AB34: SC1 | AC34: SC10 | AD34: SC18 | AE34: SC20 | AF34: Avg | AG34: Lambda | AH34: CI | AM34: SC1 | AN34: SC10 | AO34: SC18 | AP34: SC20 | AQ34: Avg | AR34: Lambda | AS34: CI
P35: SC1 | Q35: =Q28/Q$32 -> 0.49180328 | R35: =R28/R$32 -> 0.56603774 | S35: =S28/S$32 -> 0.4137931 | T35: =T28/T$32 -> 0.33333333 | U35: =AVERAGE(Q35:T35) -> 0.45124186 | V35: {=MMULT(Q28:T28,$U$35:$U$38)/U35} -> 4.2251431 | W35: =(V40-4)/3 -> 0.089737403 | AA35: SC1 | AB35: =AB28/AB$32 -> 0.59659108 | AC35: =AC28/AC$32 -> 0.46666667 | AD35: =AD28/AD$32 -> 0.63157895 | AE35: =AE28/AE$32 -> 0.60000002 | AF35: =AVERAGE(AB35:AE35) -> 0.57370918 | AG35: {=MMULT(AB28:AE28,AF35:AF38)/AF35} -> 4.1299631 | AH35: =(AG40-4)/3 -> 0.043321039 | AL35: SC1 | AM35: =AM28/AM$32 -> 0.12121212 | AN35: =AN28/AN$32 -> 0.22222222 | AO35: =AO28/AO$32 -> 0.13207547 | AP35: =AP28/AP$32 -> 0.095238095 | AQ35: =AVERAGE(AM35:AP35) -> 0.14268698 | AR35: {=MMULT(AM28:AP28,AQ35:AQ38)/AQ35} -> 4.0569992 | AS35: =(AR40-4)/3 -> 0.056721986
P36: SC10 | Q36: =Q29/Q$32 -> 0.24590164 | R36: =R29/R$32 -> 0.28301887 | S36: =S29/S$32 -> 0.4137931 | T36: =T29/T$32 -> 0.33333333 | U36: =AVERAGE(Q36:T36) -> 0.31901174 | V36: {=MMULT(Q29:T29,$U$35:$U$38)/U36} -> 4.2692122 | AA36: SC10 | AB36: =AB29/AB$32 -> 0.085227212 | AC36: =AC29/AC$32 -> 0.066666667 | AD36: =AD29/AD$32 -> 0.052631579 | AE36: =AE29/AE$32 -> 0.039999962 | AF36: =AVERAGE(AB36:AE36) -> 0.061131355 | AG36: {=MMULT(AB29:AE29,AF35:AF38)/AF36} -> 4.0196229 | AL36: SC10 | AM36: =AM29/AM$32 -> 0.03030303 | AN36: =AN29/AN$32 -> 0.055555556 | AO36: =AO29/AO$32 -> 0.075471698 | AP36: =AP29/AP$32 -> 0.047619048 | AQ36: =AVERAGE(AM36:AP36) -> 0.052237333 | AR36: {=MMULT(AM29:AP29,AQ35:AQ38)/AQ36} -> 4.0266513
P37: SC18 | Q37: =Q30/Q$32 -> 0.16393443 | R37: =R30/R$32 -> 0.094339623 | S37: =S30/S$32 -> 0.13793103 | T37: =T30/T$32 -> 0.26666667 | U37: =AVERAGE(Q37:T37) -> 0.16571794 | V37: {=MMULT(Q30:T30,$U$35:$U$38)/U37} -> 4.0948071 | AA37: SC18 | AB37: =AB30/AB$32 -> 0.19886349 | AC37: =AC30/AC$32 -> 0.26666667 | AD37: =AD30/AD$32 -> 0.21052632 | AE37: =AE30/AE$32 -> 0.24000001 | AF37: =AVERAGE(AB37:AE37) -> 0.22901412 | AG37: {=MMULT(AB30:AE30,AF35:AF38)/AF37} -> 4.0917408 | AL37: SC18 | AM37: =AM30/AM$32 -> 0.48484848 | AN37: =AN30/AN$32 -> 0.38888889 | AO37: =AO30/AO$32 -> 0.52830189 | AP37: =AP30/AP$32 -> 0.57142857 | AQ37: =AVERAGE(AM37:AP37) -> 0.49336696 | AR37: {=MMULT(AM30:AP30,AQ35:AQ38)/AQ37} -> 4.1615954
P38: SC20 | Q38: =Q31/Q$32 -> 0.098360656 | R38: =R31/R$32 -> 0.056603774 | S38: =S31/S$32 -> 0.034482759 | T38: =T31/T$32 -> 0.066666667 | U38: =AVERAGE(Q38:T38) -> 0.064028464 | V38: {=MMULT(Q31:T31,$U$35:$U$38)/U38} -> 4.0530204 | AA38: SC20 | AB38: =AB31/AB$32 -> 0.11931822 | AC38: =AC31/AC$32 -> 0.2 | AD38: =AD31/AD$32 -> 0.10526316 | AE38: =AE31/AE$32 -> 0.12 | AF38: =AVERAGE(AB38:AE38) -> 0.13614534 | AG38: {=MMULT(AB31:AE31,AF35:AF38)/AF38} -> 4.0309003 | AL38: SC20 | AM38: =AM31/AM$32 -> 0.36363636 | AN38: =AN31/AN$32 -> 0.33333333 | AO38: =AO31/AO$32 -> 0.26415094 | AP38: =AP31/AP$32 -> 0.28571429 | AQ38: =AVERAGE(AM38:AP38) -> 0.31170873 | AR38: {=MMULT(AM31:AP31,AQ35:AQ38)/AQ38} -> 4.170166
P39: Sum | Q39: =SUM(Q35:Q38) -> 1 | R39: =SUM(R35:R38) -> 1 | S39: =SUM(S35:S38) -> 1 | T39: =SUM(T35:T38) -> 1 | U39: =SUM(U35:U38) -> 1 | AA39: Sum | AB39: =SUM(AB35:AB38) -> 1 | AC39: =SUM(AC35:AC38) -> 1 | AD39: =SUM(AD35:AD38) -> 1 | AE39: =SUM(AE35:AE38) -> 1 | AF39: =SUM(AF35:AF38) -> 1 | AL39: Sum | AM39: =SUM(AM35:AM38) -> 1 | AN39: =SUM(AN35:AN38) -> 1 | AO39: =SUM(AO35:AO38) -> 1 | AP39: =SUM(AP35:AP38) -> 1 | AQ39: =SUM(AQ35:AQ38) -> 1
U40: Lambda max | V40: =MAX(V35:V38) -> 4.2692122 | AF40: Lambda max | AG40: =MAX(AG35:AG38) -> 4.1299631 | AQ40: Lambda max | AR40: =MAX(AR35:AR38) -> 4.170166
AA49: Ecosystem and biodiversity loss
AB51: SC1 | AC51: SC10 | AD51: SC18 | AE51: SC20
AA52: SC1 | AB52: 1 | AC52: 3 | AD52: 0.2 | AE52: 4
AA53: SC10 | AB53: 0.33333333 | AC53: 1 | AD53: 0.14285714 | AE53: 2
...

Sheet AHP Vs. REMBRANDT
C2: SC1 | D2: SC10 | E2: SC18 | F2: SC20
B3: AHP | C3: ='MCDA - AHP'!BH15 -> 20.610814 | D3: ='MCDA - AHP'!BI15 -> 17.171255 | E3: ='MCDA - AHP'!BJ15 -> 29.313709 | F3: ='MCDA - AHP'!BK15 -> 32.904222
B4: REMBRANDT | C4: ='MCDA - REMBRANDT'!BP15 -> 11.202224 | D4: ='MCDA - REMBRANDT'!BQ15 -> 1.7579971 | E4: ='MCDA - REMBRANDT'!BR15 -> 38.94215 | F4: ='MCDA - REMBRANDT'!BS15 -> 48.097629

Sheet MCDA - Environment
B2: C3 | C2: Ecosystem and Biodiversity Loss | W2: SC10 is rated worst (0) because it has by far the largest amount of new infrastructure, especially roads, implying the highest land-take and fragmentation. SC20 is best (100) because it focuses on upgrades in existing corridors. SC1 and SC18 sit in between: SC1 has significant new tunnel and construction footprint, while SC18 has moderate new works and upgrades.
B3: C4 | C3: Non-renewable dependence - (construction + operational) | T3: C3 | U3: Scenario | V3: Eco-system & Biodiversity Score (higher=better)
U4: SC1 | V4: 30
C5: Alternatives | U5: SC10 | V5: 0
B6: S01 | C6: Munich - Verona | U6: SC18 | V6: 60
B7: S10 | C7: Hungary - Romania + Bulgary - Greece | U7: SC20 | V7: 100
B8: S18 | C8: Fehmarn Belt (incl. upgrades)
B9: S20 | C9: Upgrades in Cologne
T10: C4 | U10: Scenario | V10: Non-renewable Dependence Score | W10: SC1 is best (100) because it is almost entirely rail-oriented, supporting a shift away from oil-dependent road transport. SC10 is worst (0) as it massively expands the road network, reinforcing oil dependence. SC18 mixes new road and new rail but leans more than SC20 toward improving rail, so it gets a higher score than SC20, which mainly upgrades roads.
U11: SC1 | V11: 100
U12: SC10 | V12: 0
U13: SC18 | V13: 70
U14: SC20 | V14: 30
U18: AHP | AB18: REMBRANDT
U19: C3 | AB19: C3
V20: SC1 | W20: SC10 | X20: SC18 | Y20: SC20 | AC20: SC1 | AD20: SC10 | AE20: SC18 | AF20: SC20
U21: SC1 | V21: 1 | W21: 3 | X21: 0.333333 | Y21: 0.2 | AB21: SC1 | AC21: 0 | AD21: 2 | AE21: -4 | AF21: -6
A22: AHP | K22: REMBRANDT | U22: SC10 | V22: 0.333333 | W22: 1 | X22: 0.2 | Y22: 0.111111 | AB22: SC10 | AC22: -2 | AD22: 0 | AE22: -6 | AF22: -8
U23: SC18 | V23: 3 | W23: 5 | X23: 1 | Y23: 0.333333 | AB23: SC18 | AC23: 4 | AD23: 6 | AE23: 0 | AF23: -4
U24: SC20 | V24: 5 | W24: 9 | X24: 3 | Y24: 1 | AB24: SC20 | AC24: 6 | AD24: 8 | AE24: 4 | AF24: 0
U28: C4 | AB28: C4
V29: SC1 | W29: SC10 | X29: SC18 | Y29: SC20 | AC29: SC1 | AD29: SC10 | AE29: SC18 | AF29: SC20
U30: SC1 | V30: 1 | W30: 9 | X30: 3 | Y30: 7 | AB30: SC1 | AC30: 0 | AD30: 6 | AE30: 4 | AF30: 4
U31: SC10 | V31: 0.111111 | W31: 1 | X31: 0.142857 | Y31: 0.333333 | AB31: SC10 | AC31: -6 | AD31: 0 | AE31: -4 | AF31: -2
U32: SC18 | V32: 0.333333 | W32: 7 | X32: 1 | Y32: 5 | AB32: SC18 | AC32: -4 | AD32: 4 | AE32: 0 | AF32: 2
U33: SC20 | V33: 0.142857 | W33: 3 | X33: 0.2 | Y33: 1 | AB33: SC20 | AC33: -4 | AD33: 2 | AE33: -2 | AF33: 0
B50: 1. Ecosystem/Biodiversity Impact (from weakest → strongest impact) | M50: based on reports from the relevant countries on individual parts of the larger scenarios
B51: Least impact
B52: → Sc 20 (urban, avoids Natura 2000 sites)
B53: → Sc 10 (fragmented, small Natura 2000 % impacts)
B54: → Sc 1 (Alpine ecosystem risk, groundwater, habitat fragmentation)
B55: → Sc 18 (largest quantified marine impacts + dredging + sensitive species)
B56: Most impact
B57: 2. Fossil-Fuel Dependency (from best → worst) | J57: taken into account: modal shift, energy mix, traffic growth
B58: Most reduction in fossil-fuel dependence
B59: → Sc 1 (strong road→rail shift)
B60: → Sc 20 (freight-reliability → diesel reduction)
B61: → Sc 10 (moderate modal shift potential)
B62: → Sc 18 (big road-traffic growth risk → diesel increase)
B63: Least reduction / possible increase
...

Sheet MCDA - Social
I2: AHP
B3: Criteria | C3: Name | D3: Explanation | I3: Criterion 5
B4: C5 | C4: Labour market and sociographic job distribution | D4: Net Jobs created and duration | F4: entries >1 mean row i preferred over column j by that factor; | J4: SC1 | K4: SC10 | L4: SC18 | M4: SC20 | N4: CI
B5: C6 | C5: Territorial cohesion | D5: https://www.tandfonline.com/doi/full/10.1080/09654313.2022.2143713#d1e381 | I5: SC1 | J5: 1 | K5: 2 | L5: =1/3 -> 0.33333333 | M5: 5 | N5: ='MCDA - AHP'!W17 -> 0.08173434
I6: SC10 | J6: =1/K5 -> 0.5 | K6: 1 | L6: =1/4 -> 0.25 | M6: 5
C7: Alternatives | I7: SC18 | J7: =1/L5 -> 3 | K7: =1/L6 -> 4 | L7: 1 | M7: 7
B8: S01 | C8: Munich - Verona | I8: SC20 | J8: =1/M5 -> 0.2 | K8: =1/M6 -> 0.2 | L8: =1/M7 -> 0.14285714 | M8: 1
B9: S10 | C9: Hungary - Romania + Bulgary - Greece
B10: S18 | C10: Fehmarn Belt (incl. upgrades) | I10: Criterion 6
B11: S20 | C11: Upgrades in Cologne | J11: SC1 | K11: SC10 | L11: SC18 | M11: SC20 | N11: CI
I12: SC1 | J12: 1 | K12: 2 | L12: 3 | M12: 5 | N12: ='MCDA - AHP'!W35 -> 0.089737403
I13: SC10 | J13: =1/K12 -> 0.5 | K13: 1 | L13: 3 | M13: 5
I14: SC18 | J14: =1/L12 -> 0.33333333 | K14: =1/L13 -> 0.33333333 | L14: 1 | M14: 4
I15: SC20 | J15: =1/M12 -> 0.2 | K15: =1/M13 -> 0.2 | L15: =1/M14 -> 0.25 | M15: 1
I17: REMBRANDT
I18: Criterion 5
J19: SC1 | K19: SC10 | L19: SC18 | M19: SC20
I20: SC1 | J20: 0 | K20: 4 | L20: -4 | M20: 6
I21: SC10 | J21: =-K20 -> -4 | K21: 0 | L21: -2 | M21: 6
I22: SC18 | J22: =-L20 -> 4 | K22: =-L21 -> 2 | L22: 0 | M22: 6
I23: SC20 | J23: =-M20 -> -6 | K23: =-M21 -> -6 | L23: =-M22 -> -6 | M23: 0
I25: Criterion 6
J26: SC1 | K26: SC10 | L26: SC18 | M26: SC20
I27: SC1 | J27: 0 | K27: 2 | L27: 4 | M27: 6
I28: SC10 | J28: =-K27 -> -2 | K28: 0 | L28: 4 | M28: 6
I29: SC18 | J29: =-L27 -> -4 | K29: =-L28 -> -4 | L29: 0 | M29: 6
I30: SC20 | J30: =-M27 -> -6 | K30: =-M28 -> -6 | L30: =-M29 -> -6 | M30: 0
B43: AHP | D43: REMBRANDT
B66: Criteria | C66: C5
B67: SC1 | C67: Capital intensive tunnel construction and long upgrades (55 km new Tunnel railway, 293 + 326 rail upgrades)
B68: SC10 | C68: Extremely large total length of works (456 km new roads, 52 km new railways, 850 + 931 km upgrade rail)
B69: SC18 | C69: Bridge + new rail line + upgrades rail (19 km new roads, 19 km new rail, 358 + 490 rail upgrades)
B70: SC20 | C70: Localized upgrades - 625 km road upgrades, 130 + 246 rail upgrades
C72: Additional | D72: New Roads (km) | E72: New Rail (km) | F72: Road Upgrade (km) | G72: Upgrade passenger rail (km) | H72: Upgrade Freight rail (km) | I72: Total Rail works | J72: Total Road works | K72: Works (jobs + rail)
B73: SC1 | C73: Tunnel Construction - 55 km | D73: 0 | E73: 55 | F73: 0 | G73: 293 | H73: 326 | I73: =G73+H73 -> 619 | J73: =E73+F73 -> 55 | K73: =I73+(J73*1.7) -> 712.5
B74: SC10 | D74: 456 | E74: 52 | F74: 0 | G74: 850 | H74: 931 | I74: =G74+H74 -> 1781 | J74: =E74+F74 -> 52 | K74: =I74+(J74*1.7) -> 1869.4
B75: SC18 | C75: Tunnel Construction underwater - 19 km | D75: 19 | E75: 19 | F75: 0 | G75: 358 | H75: 490 | I75: =G75+H75 -> 848 | J75: =E75+F75 -> 19 | K75: =I75+(J75*1.7) -> 880.3
B76: SC20 | D76: 0 | E76: 0 | F76: 625 | G76: 130 | H76: 246 | I76: =G76+H76 -> 376 | J76: =E76+F76 -> 625 | K76: =I76+(J76*1.7) -> 1438.5
C78: This creates more job | D78: than | E78: Source
B79: 1 | C79: Road Upgrades per km | D79: New Roads per km | E79: https://t4america.org/2021/03/15/road-and-public-transit-maintenance-creates-more-jobs-than-building-new-highways/
...

Sheet MCDA - Economic
B2: Alternatives | H2: Criteria
B3: Sc1 | C3: Munich - Verona | H3: C1 | I3: Intergration of European Transport
B4: Sc10 | C4: Hungary - Romania + Bulgary - Greece | H4: C2 | I4: Location of companies and logiqtic centers
B5: Sc18 | C5: Fehmarn Belt (incl. upgrades)
B6: Sc20 | C6: Upgrades in Cologne
N7: Sc1 | O7: Upgrade railway between munchen and kufstein
O8: New railway tunnel between Innsbruck and Fortezza (brenner tunnel)
O9: Upgrade railway southern end of brenner tunnel and verona
N11: Sc10 | O11: Upgrade and new railway between Kulata and Calafat
O12: Upgrade railway between calafat and arad
O13: Upgrade motorway between Vraca-Lugoj, Timisoara-hungarion border, and 80km nort of Kulata
N15: Sc18 | O15: Construction of rail/road bridge between fehrman strait, puttgarden and roedby
O16: upgrade of acces routes to planned fehrman belt between Copenhagen-roedby and puttgarden-hamburg
O17: New railwar between hannover and hambur/bremen
N19: Sc20 | O19: New railway between frankfurt and mannheim
O20: upgrading rail and road corridors around cologne
N23: C1 | O23: Intergration of European Transport
O24: Interaction with the bussiest transport routes
V25: AHP
O26: Sc1 | P26: 11.55 million passenger cars | W26: SC1 | X26: SC10 | Y26: SC18 | Z26: SC20
P27: 40 million tonnes of freight per year | V27: SC1 | W27: 1 | X27: 5 | Y27: =1/3 -> 0.33333333 | Z27: =1/3 -> 0.33333333
V28: SC10 | W28: =1/X27 -> 0.2 | X28: 1 | Y28: =1/7 -> 0.14285714 | Z28: =1/7 -> 0.14285714
O29: Sc10 | P29: 1.44 million viechicles in total | V29: SC18 | W29: =1/Y27 -> 3 | X29: =1/Y28 -> 7 | Y29: 1 | Z29: =1/2 -> 0.5
P30: 15.26 milliones tonnes of freight per year | V30: SC20 | W30: =1/Z27 -> 3 | X30: =1/Z28 -> 7 | Y30: =1/Z29 -> 2 | Z30: 1
V31: Sum | W31: =SUM(W27:W30) -> 7.2 | X31: =SUM(X27:X30) -> 20 | Y31: =SUM(Y27:Y30) -> 3.4761905 | Z31: =SUM(Z27:Z30) -> 1.9761905
O32: Sc18 | P32: 1.2 million passengers yearly
P33: 56 million tonnes of freight annually (will grow drastically) | W33: SC1 | X33: SC10 | Y33: SC18 | Z33: SC20 | AA33: AVG | AB33: Lambda
V34: SC1 | W34: =W27/$W$31 -> 0.13888889 | X34: =X27/$X$31 -> 0.25 | Y34: =Y27/$Y$31 -> 0.095890411 | Z34: =Z27/$Z$31 -> 0.1686747 | AA34: =AVERAGE(W34:Z34) -> 0.1633635 | AB34: {=MMULT($W$27:$Z$27,$AA$34:$AA$37)/AA34} -> 4.0723027 | AC34: =(MAX(AB34:AB37)-4)/3 -> 0.076610077
O35: Sc20 | P35: 15 million yearly passengers | V35: SC10 | W35: =W28/$W$31 -> 0.027777778 | X35: =X28/$X$31 -> 0.05 | Y35: =Y28/$Y$31 -> 0.04109589 | Z35: =Z28/$Z$31 -> 0.072289157 | AA35: =AVERAGE(W35:Z35) -> 0.047790706 | AB35: {=MMULT($W$28:$Z$28,$AA$34:$AA$37)/AA35} -> 4.0416993
P36: 56.16 million tonnes of freight annually | V36: SC18 | W36: =W29/$W$31 -> 0.41666667 | X36: =X29/$X$31 -> 0.35 | Y36: =Y29/$Y$31 -> 0.28767123 | Z36: =Z29/$Z$31 -> 0.25301205 | AA36: =AVERAGE(W36:Z36) -> 0.32683749 | AB36: {=MMULT($W$29:$Z$29,$AA$34:$AA$37)/AA36} -> 4.2298302
V37: SC20 | W37: =W30/$W$31 -> 0.41666667 | X37: =X30/$X$31 -> 0.35 | Y37: =Y30/$Y$31 -> 0.57534247 | Z37: =Z30/$Z$31 -> 0.5060241 | AA37: =AVERAGE(W37:Z37) -> 0.46200831 | AB37: {=MMULT($W$30:$Z$30,$AA$34:$AA$37)/AA37} -> 4.1997269
W38: =SUM(W34:W37) -> 1 | X38: =SUM(X34:X37) -> 1 | Y38: =SUM(Y34:Y37) -> 1 | Z38: =SUM(Z34:Z37) -> 1
V41: Rembrandt
W42: SC1 | X42: SC10 | Y42: SC18 | Z42: SC20
V43: SC1 | W43: 0 | X43: 4 | Y43: -2 | Z43: -4
V44: SC10 | W44: =-X43 -> -4 | X44: 0 | Y44: -6 | Z44: -6
V45: SC18 | W45: =-Y43 -> 2 | X45: =-Y44 -> 6 | Y45: 0 | Z45: -2
V46: SC20 | W46: =-Z43 -> 4 | X46: =-Z44 -> 6 | Y46: =-Z45 -> 2 | Z46: 0
N48: C2 | O48: Location of companies and logiqtic centers
O49: Connextions of industrial zones and hubs
...

Sheet MCDA - REMBRANDT
P2: REMBRANDT
P4: Social | AA4: Environmental | AK4: C1 | AL4: Economic
O6: C5 | P6: Labour market and sociographic job distribution | Z6: C3 | AA6: Ecosystem and biodiversity loss | AL6: Integration of European transport | AW6: Criterias - Sensitivity Analysis | BP6: Geometric Mean Scores
BM7: Criteria | BO7: Weights | BP7: SC1 | BQ7: SC10 | BR7: SC18 | BS7: SC20
AW8: Baseline | BM8: Economic | BN8: Integration of European transport | BO8: =BK10 -> 0.45886377 | BP8: =$AU$10 -> 0.70710678 | BQ8: =$AU$11 -> 0.0625 | BR8: =$AU$12 -> 2.8284271 | BS8: =$AU$13 -> 8
